#VRML_SIM R2025a utf8

EXTERNPROTO "https://raw.githubusercontent.com/cyberbotics/webots/R2025a/projects/objects/backgrounds/protos/TexturedBackground.proto"
EXTERNPROTO "https://raw.githubusercontent.com/cyberbotics/webots/R2025a/projects/objects/backgrounds/protos/TexturedBackgroundLight.proto"
EXTERNPROTO "https://raw.githubusercontent.com/cyberbotics/webots/R2025a/projects/objects/floors/protos/RectangleArena.proto"
EXTERNPROTO "https://raw.githubusercontent.com/cyberbotics/webots/R2025a/projects/appearances/protos/Parquetry.proto"

WorldInfo {
}
Viewpoint {
  orientation -0.22621903483761696 0.3997686399970203 0.8882623389247513 1.054045364897764
  position -2.0667200369226086 -2.96126071140145 1.915006017319906
}
TexturedBackground {
}
TexturedBackgroundLight {
}
RectangleArena {
  floorSize 3 3
  floorAppearance Parquetry {
    type "light strip"
  }
}
Viewpoint {
  orientation 0.2917630075489508 0.8745998678638741 0.38723302875463084 0.3954160637099708
  position -0.222878874796543 -0.07278553945594193 0.07819211933123807
}
TexturedBackground {
}
TexturedBackgroundLight {
  luminosity 0
}
RectangleArena {
  floorSize 3 3
  floorAppearance Parquetry {
    type "light strip"
  }
}
Robot {
  translation -0.015080181020876278 -0.007033851428018116 0.015974000461924855
  rotation 0.871155124586174 -0.014188544678747517 -0.49080284647416916 0.06627098847109121
  children [
    HingeJoint {
      jointParameters HingeJointParameters {
        position -1.1580487005550731e-08
        axis 1 0 0
      }
      device [
        DEF LeftMotor RotationalMotor {
          name "LeftMotor"
        }
      ]
      endPoint Solid {
        translation -9.221209522890433e-07 5.124315657998452e-08 5.482676621107805e-07
        rotation 0.7528994690376299 0.6219710486808522 0.21516134440390516 1.6858739404357617e-07
        children [
          DEF LeftWheel Shape {
            appearance PBRAppearance {
              roughness 1
              metalness 0
            }
            geometry Mesh {
              url [
                "../../../Downloads/LeftWheel5.obj"
              ]
            }
            castShadows FALSE
            isPickable FALSE
          }
        ]
        name "solid(1)"
        boundingObject USE LeftWheel
        physics DEF LeftWheelPhysic Physics {
        }
      }
    }
    HingeJoint {
      jointParameters HingeJointParameters {
        position 1.1580492317457738e-08
        axis 1 0 0
      }
      device [
        DEF RightMotor RotationalMotor {
          name "RightMotor"
        }
      ]
      endPoint Solid {
        translation 2.405043405586135e-07 2.508370214836242e-08 4.4343854579586096e-07
        rotation 0 1 0 0
        children [
          DEF RightWheel Shape {
            appearance PBRAppearance {
              roughness 1
              metalness 0
            }
            geometry Mesh {
              url [
                "../../../Downloads/RightWheel6.obj"
              ]
            }
            castShadows FALSE
            isPickable FALSE
          }
        ]
        boundingObject USE RightWheel
        physics DEF RightWheelPhysic Physics {
        }
      }
    }
    DEF Body Shape {
      appearance PBRAppearance {
        baseColor 0.988235 1 0.941176
        roughness 1
        metalness 0
      }
      geometry Mesh {
        url [
          "../../../Downloads/MainBody.obj"
        ]
      }
      castShadows FALSE
      isPickable FALSE
    }
  ]
  boundingObject USE Body
  physics Physics {
    centerOfMass [
      0 0 0
    ]
  }
  controller "my_controller"
  linearVelocity -3.92271656612485e-09 -1.1725661098280804e-07 9.057317080009897e-09
  angularVelocity 7.338984233984705e-06 -2.4550944174900817e-07 2.990316232364208e-10
}
