#VRML_SIM R2025a utf8

EXTERNPROTO "https://raw.githubusercontent.com/cyberbotics/webots/R2025a/projects/objects/backgrounds/protos/TexturedBackground.proto"
EXTERNPROTO "https://raw.githubusercontent.com/cyberbotics/webots/R2025a/projects/objects/backgrounds/protos/TexturedBackgroundLight.proto"
EXTERNPROTO "https://raw.githubusercontent.com/cyberbotics/webots/R2025a/projects/objects/floors/protos/RectangleArena.proto"
EXTERNPROTO "https://raw.githubusercontent.com/cyberbotics/webots/R2025a/projects/appearances/protos/Parquetry.proto"

WorldInfo {
}
Viewpoint {
  orientation -0.22621903483761696 0.3997686399970203 0.8882623389247513 1.054045364897764
  position -2.0667200369226086 -2.96126071140145 1.915006017319906
}
TexturedBackground {
}
TexturedBackgroundLight {
}
RectangleArena {
  floorSize 3 3
  floorAppearance Parquetry {
    type "light strip"
  }
}
Viewpoint {
  orientation -0.25831873427465113 0.14184218383059116 0.9555899886504206 2.79994345311428
  position 0.23955951513902918 -0.133591745749582 0.1641573916201528
}
TexturedBackground {
}
TexturedBackgroundLight {
  luminosity 0
}
RectangleArena {
  floorSize 3 3
  floorAppearance Parquetry {
    type "light strip"
  }
}
Robot {
  translation -0.016847 -0.00479802 0.0289494
  children [
    HingeJoint {
      jointParameters HingeJointParameters {
        axis 0 1 0
      }
      device [
        DEF LeftMotor RotationalMotor {
          name "LeftMotor"
        }
      ]
      endPoint Solid {
        children [
          DEF LeftWheel Shape {
            appearance PBRAppearance {
              roughness 1
              metalness 0
            }
            geometry Mesh {
              url [
                "../../../Downloads/LeftWheel2.obj"
              ]
            }
          }
        ]
        name "solid(1)"
        boundingObject USE LeftWheel
        physics DEF LeftWheelPhysic Physics {
        }
      }
    }
    HingeJoint {
      jointParameters HingeJointParameters {
        axis 0 1 0
      }
      device [
        DEF RightMotor RotationalMotor {
          name "RightMotor"
        }
      ]
      endPoint Solid {
        children [
          DEF RightWheel Shape {
            appearance PBRAppearance {
              roughness 1
              metalness 0
            }
            geometry Mesh {
              url [
                "../../../Downloads/RightWheel3.obj"
              ]
            }
          }
        ]
        boundingObject USE RightWheel
        physics DEF RightWheelPhysic Physics {
        }
      }
    }
    DEF Body Shape {
      appearance PBRAppearance {
        baseColor 0.988235 1 0.941176
        roughness 1
        metalness 0
      }
      geometry Mesh {
        url [
          "../../../Downloads/bottom3.obj"
        ]
      }
    }
  ]
  boundingObject USE Body
  physics Physics {
    centerOfMass [
      0 0 0
    ]
  }
  controller "<none>"
}
