#VRML_SIM R2025a utf8

EXTERNPROTO "https://raw.githubusercontent.com/cyberbotics/webots/R2025a/projects/objects/backgrounds/protos/TexturedBackground.proto"
EXTERNPROTO "https://raw.githubusercontent.com/cyberbotics/webots/R2025a/projects/objects/backgrounds/protos/TexturedBackgroundLight.proto"
EXTERNPROTO "https://raw.githubusercontent.com/cyberbotics/webots/R2025a/projects/objects/floors/protos/RectangleArena.proto"

WorldInfo {
  contactProperties [
    ContactProperties {
      material1 "rubber"
      material2 "parchment_paper"
      coulombFriction [
        0.4
      ]
    }
    ContactProperties {
      material1 "rubber"
      material2 "ground"
      coulombFriction [
        0.8
      ]
    }
    ContactProperties {
      material1 "rubber"
      material2 "whiteboard"
      coulombFriction [
        0.7
      ]
    }
    ContactProperties {
      material1 "rubber"
      material2 "bumpGround"
      coulombFriction [
        0.85
      ]
    }
  ]
}
Viewpoint {
  orientation -0.22621903483761696 0.3997686399970203 0.8882623389247513 1.054045364897764
  position -2.0667200369226086 -2.96126071140145 1.915006017319906
}
TexturedBackground {
}
TexturedBackgroundLight {
}
Viewpoint {
  orientation -0.2986345297254392 -0.13382877084437927 0.944937711042346 4.199908390858644
  position 0.5876449049294323 1.9124013117655696 1.2825658392831245
}
TexturedBackground {
}
TexturedBackgroundLight {
  luminosity 0
}
RectangleArena {
  contactMaterial "parchment_paper"
  floorSize 3 3
}
DEF WAYPOINT_MARKER Solid {
  translation 0.3832 -0.0597 0.002
  children [
    Shape {
      appearance PBRAppearance {
        baseColor 1 0 0
        transparency 0.8
        roughness 1
        metalness 0
        emissiveColor 1 0 0
      }
      geometry Cylinder {
        height 1
        radius 0.03
      }
    }
  ]
}
DEF POLULU_ROBOT Robot {
  translation 0.423732 -0.0586536 0.270771
  rotation 0.20326832756627855 0.1990047631574995 0.9586861275980975 1.7447669415462497
  children [
    Display {
      width 230
    }
    InertialUnit {
      name "imu"
    }
    GPS {
    }
    Shape {
      appearance PBRAppearance {
        roughness 1
        metalness 0
      }
      geometry Mesh {
        url [
          "../../../Downloads/bodywithoutcaster.obj"
        ]
      }
      castShadows FALSE
      isPickable FALSE
    }
    BallJoint {
      jointParameters BallJointParameters {
        position -1424.724187096699
        anchor 0 0.0404 -0.0096
      }
      jointParameters2 JointParameters {
        position 31.45644367452406
        axis 1 0 0
      }
      jointParameters3 JointParameters {
        position -9.233429299345156
        axis 0 1 0
      }
      endPoint Solid {
        translation 0.015533171459676517 0.07538236776384996 -0.026084246671253225
        rotation 0.2694912459670977 0.21260129521537918 0.939241799335956 2.742845918245766
        children [
          Shape {
            appearance PBRAppearance {
              roughness 1
              metalness 0
            }
            geometry Mesh {
              url [
                "../Models/caster.obj"
              ]
            }
            castShadows FALSE
            isPickable FALSE
          }
        ]
        name "caster"
        boundingObject Pose {
          translation 0 0.0404 -0.00963
          children [
            Sphere {
              radius 0.00635
              subdivision 3
            }
          ]
        }
        physics Physics {
        }
      }
    }
    HingeJoint {
      jointParameters HingeJointParameters {
        position 2329.773170279202
      }
      device [
        RotationalMotor {
          name "LeftMotor"
          maxVelocity 75.4
        }
      ]
      endPoint Solid {
        translation 0.041499474598696594 -5.381046464216315e-05 0.0003672061039292856
        rotation -0.44429116540923475 -0.7815648620432041 0.4379060707031722 1.8125663006538448
        children [
          DEF wheel Shape {
            appearance PBRAppearance {
              roughness 1
              metalness 0
            }
            geometry Cylinder {
              height 0.0068
              radius 0.016
              subdivision 500
            }
            castShadows FALSE
            isPickable FALSE
          }
        ]
        contactMaterial "rubber"
        boundingObject USE wheel
        physics Physics {
        }
      }
    }
    HingeJoint {
      jointParameters HingeJointParameters {
        position 3207.544228868219
      }
      device [
        DEF RightMotor RotationalMotor {
          name "RightMotor"
          maxVelocity 75.4
        }
      ]
      endPoint Solid {
        translation -0.04149868078943602 -0.0002879916101905366 -0.00043751805057454403
        rotation -0.7088474696269592 -0.008266141268160325 -0.7053133599415171 3.15615019385823
        children [
          USE wheel
        ]
        contactMaterial "rubber"
        boundingObject USE wheel
        physics Physics {
        }
      }
    }
  ]
  boundingObject Pose {
    translation 0 0 0.0025
    children [
      Cylinder {
        height 0.0266
        radius 0.0484
        subdivision 50
      }
    ]
  }
  physics Physics {
    mass 0.158
    centerOfMass [
      0 0 0
    ]
  }
  controller "autonomous_navigation"
  supervisor TRUE
}
Solid {
  translation -0.29 -0.07 0
  rotation 4.2287116815538744e-08 -0.7071042811811333 -0.7071092811831217 3.1415853071795863
  children [
    DEF obstacle Shape {
      appearance PBRAppearance {
        baseColor 0 0 0
        roughness 1
        metalness 0
      }
      geometry Mesh {
        url [
          "../../../Downloads/ramp1.obj"
        ]
      }
    }
  ]
  name "ramp"
  contactMaterial "whiteboard"
  boundingObject Group {
    children [
      Pose {
        translation -0.564 0.092 0
        rotation 0 0 1 0.24043831505672397
        children [
          Box {
            size 0.76 0.1 0.28
          }
        ]
      }
      Pose {
        translation -0.0024 0.104 0
        rotation 0 0 1 -0.085
        children [
          Box {
            size 0.25 0.25 0.31
          }
        ]
        rotationStep 0.343
      }
      Pose {
        translation -0.123 -0.1951 0
        children [
          Capsule {
            height 0.4
            radius 0.434
            subdivision 500
          }
        ]
      }
    ]
  }
}
Solid {
  translation 0.58 1.44 5.67207e-06
  rotation 0.5773509358554485 0.5773489358556708 0.5773509358554485 2.0944
  children [
    DEF bump Shape {
      appearance PBRAppearance {
        baseColor 0 0 0
        roughness 1
        metalness 0
      }
      geometry Mesh {
        url [
          "../../../Downloads/bump.obj"
        ]
      }
    }
  ]
  name "bump"
  contactMaterial "bumpGround"
  boundingObject Group {
    children [
      Pose {
        translation -0.97 0.0052 -0.01
        children [
          Box {
            size 0.02 0.004 0.02
          }
        ]
      }
      Pose {
        translation -0.97 0.0052 -0.07
        children [
          Box {
            size 0.02 0.004 0.02
          }
        ]
      }
      Pose {
        translation -0.97 0.0052 -0.13
        children [
          Box {
            size 0.02 0.004 0.02
          }
        ]
      }
      Pose {
        translation -0.97 0.0052 -0.19
        children [
          Box {
            size 0.02 0.004 0.02
          }
        ]
      }
      Pose {
        translation -0.97 0.0052 -0.25
        children [
          Box {
            size 0.02 0.004 0.02
          }
        ]
      }
      Pose {
        translation -0.97 0.0052 -0.31
        children [
          Box {
            size 0.02 0.004 0.02
          }
        ]
      }
      Pose {
        translation -0.91 0.0052 -0.01
        children [
          Box {
            size 0.02 0.004 0.02
          }
        ]
      }
      Pose {
        translation -0.91 0.0052 -0.07
        children [
          Box {
            size 0.02 0.004 0.02
          }
        ]
      }
      Pose {
        translation -0.91 0.0052 -0.13
        children [
          Box {
            size 0.02 0.004 0.02
          }
        ]
      }
      Pose {
        translation -0.91 0.0052 -0.19
        children [
          Box {
            size 0.02 0.004 0.02
          }
        ]
      }
      Pose {
        translation -0.91 0.0052 -0.25
        children [
          Box {
            size 0.02 0.004 0.02
          }
        ]
      }
      Pose {
        translation -0.91 0.0052 -0.31
        children [
          Box {
            size 0.02 0.004 0.02
          }
        ]
      }
      Pose {
        translation -0.85 0.0052 -0.01
        children [
          Box {
            size 0.02 0.004 0.02
          }
        ]
      }
      Pose {
        translation -0.85 0.0052 -0.07
        children [
          Box {
            size 0.02 0.004 0.02
          }
        ]
      }
      Pose {
        translation -0.85 0.0052 -0.13
        children [
          Box {
            size 0.02 0.004 0.02
          }
        ]
      }
      Pose {
        translation -0.85 0.0052 -0.19
        children [
          Box {
            size 0.02 0.004 0.02
          }
        ]
      }
      Pose {
        translation -0.85 0.0052 -0.25
        children [
          Box {
            size 0.02 0.004 0.02
          }
        ]
      }
      Pose {
        translation -0.85 0.0052 -0.31
        children [
          Box {
            size 0.02 0.004 0.02
          }
        ]
      }
      Pose {
        translation -0.79 0.0052 -0.01
        children [
          Box {
            size 0.02 0.004 0.02
          }
        ]
      }
      Pose {
        translation -0.79 0.0052 -0.07
        children [
          Box {
            size 0.02 0.004 0.02
          }
        ]
      }
      Pose {
        translation -0.79 0.0052 -0.13
        children [
          Box {
            size 0.02 0.004 0.02
          }
        ]
      }
      Pose {
        translation -0.79 0.0052 -0.19
        children [
          Box {
            size 0.02 0.004 0.02
          }
        ]
      }
      Pose {
        translation -0.79 0.0052 -0.25
        children [
          Box {
            size 0.02 0.004 0.02
          }
        ]
      }
      Pose {
        translation -0.79 0.0052 -0.31
        children [
          Box {
            size 0.02 0.004 0.02
          }
        ]
      }
      Pose {
        translation -0.73 0.0052 -0.01
        children [
          Box {
            size 0.02 0.004 0.02
          }
        ]
      }
      Pose {
        translation -0.73 0.0052 -0.07
        children [
          Box {
            size 0.02 0.004 0.02
          }
        ]
      }
      Pose {
        translation -0.73 0.0052 -0.13
        children [
          Box {
            size 0.02 0.004 0.02
          }
        ]
      }
      Pose {
        translation -0.73 0.0052 -0.19
        children [
          Box {
            size 0.02 0.004 0.02
          }
        ]
      }
      Pose {
        translation -0.73 0.0052 -0.25
        children [
          Box {
            size 0.02 0.004 0.02
          }
        ]
      }
      Pose {
        translation -0.73 0.0052 -0.31
        children [
          Box {
            size 0.02 0.004 0.02
          }
        ]
      }
      Pose {
        translation -0.67 0.0052 -0.01
        children [
          Box {
            size 0.02 0.004 0.02
          }
        ]
      }
      Pose {
        translation -0.67 0.0052 -0.07
        children [
          Box {
            size 0.02 0.004 0.02
          }
        ]
      }
      Pose {
        translation -0.67 0.0052 -0.13
        children [
          Box {
            size 0.02 0.004 0.02
          }
        ]
      }
      Pose {
        translation -0.67 0.0052 -0.19
        children [
          Box {
            size 0.02 0.004 0.02
          }
        ]
      }
      Pose {
        translation -0.67 0.0052 -0.25
        children [
          Box {
            size 0.02 0.004 0.02
          }
        ]
      }
      Pose {
        translation -0.67 0.0052 -0.31
        children [
          Box {
            size 0.02 0.004 0.02
          }
        ]
      }
      Pose {
        translation -0.61 0.0052 -0.01
        children [
          Box {
            size 0.02 0.004 0.02
          }
        ]
      }
      Pose {
        translation -0.61 0.0052 -0.07
        children [
          Box {
            size 0.02 0.004 0.02
          }
        ]
      }
      Pose {
        translation -0.61 0.0052 -0.13
        children [
          Box {
            size 0.02 0.004 0.02
          }
        ]
      }
      Pose {
        translation -0.61 0.0052 -0.19
        children [
          Box {
            size 0.02 0.004 0.02
          }
        ]
      }
      Pose {
        translation -0.61 0.0052 -0.25
        children [
          Box {
            size 0.02 0.004 0.02
          }
        ]
      }
      Pose {
        translation -0.61 0.0052 -0.31
        children [
          Box {
            size 0.02 0.004 0.02
          }
        ]
      }
      Pose {
        translation -0.55 0.0052 -0.01
        children [
          Box {
            size 0.02 0.004 0.02
          }
        ]
      }
      Pose {
        translation -0.55 0.0052 -0.07
        children [
          Box {
            size 0.02 0.004 0.02
          }
        ]
      }
      Pose {
        translation -0.55 0.0052 -0.13
        children [
          Box {
            size 0.02 0.004 0.02
          }
        ]
      }
      Pose {
        translation -0.55 0.0052 -0.19
        children [
          Box {
            size 0.02 0.004 0.02
          }
        ]
      }
      Pose {
        translation -0.55 0.0052 -0.25
        children [
          Box {
            size 0.02 0.004 0.02
          }
        ]
      }
      Pose {
        translation -0.55 0.0052 -0.31
        children [
          Box {
            size 0.02 0.004 0.02
          }
        ]
      }
      Pose {
        translation -0.49 0.0052 -0.01
        children [
          Box {
            size 0.02 0.004 0.02
          }
        ]
      }
      Pose {
        translation -0.49 0.0052 -0.07
        children [
          Box {
            size 0.02 0.004 0.02
          }
        ]
      }
      Pose {
        translation -0.49 0.0052 -0.13
        children [
          Box {
            size 0.02 0.004 0.02
          }
        ]
      }
      Pose {
        translation -0.49 0.0052 -0.19
        children [
          Box {
            size 0.02 0.004 0.02
          }
        ]
      }
      Pose {
        translation -0.49 0.0052 -0.25
        children [
          Box {
            size 0.02 0.004 0.02
          }
        ]
      }
      Pose {
        translation -0.49 0.0052 -0.31
        children [
          Box {
            size 0.02 0.004 0.02
          }
        ]
      }
      Pose {
        translation -0.43 0.0052 -0.01
        children [
          Box {
            size 0.02 0.004 0.02
          }
        ]
      }
      Pose {
        translation -0.43 0.0052 -0.07
        children [
          Box {
            size 0.02 0.004 0.02
          }
        ]
      }
      Pose {
        translation -0.43 0.0052 -0.13
        children [
          Box {
            size 0.02 0.004 0.02
          }
        ]
      }
      Pose {
        translation -0.43 0.0052 -0.19
        children [
          Box {
            size 0.02 0.004 0.02
          }
        ]
      }
      Pose {
        translation -0.43 0.0052 -0.25
        children [
          Box {
            size 0.02 0.004 0.02
          }
        ]
      }
      Pose {
        translation -0.43 0.0052 -0.31
        children [
          Box {
            size 0.02 0.004 0.02
          }
        ]
      }
      Pose {
        translation -0.37 0.0052 -0.01
        children [
          Box {
            size 0.02 0.004 0.02
          }
        ]
      }
      Pose {
        translation -0.37 0.0052 -0.07
        children [
          Box {
            size 0.02 0.004 0.02
          }
        ]
      }
      Pose {
        translation -0.37 0.0052 -0.13
        children [
          Box {
            size 0.02 0.004 0.02
          }
        ]
      }
      Pose {
        translation -0.37 0.0052 -0.19
        children [
          Box {
            size 0.02 0.004 0.02
          }
        ]
      }
      Pose {
        translation -0.37 0.0052 -0.25
        children [
          Box {
            size 0.02 0.004 0.02
          }
        ]
      }
      Pose {
        translation -0.37 0.0052 -0.31
        children [
          Box {
            size 0.02 0.004 0.02
          }
        ]
      }
      Pose {
        translation -0.31 0.0052 -0.01
        children [
          Box {
            size 0.02 0.004 0.02
          }
        ]
      }
      Pose {
        translation -0.31 0.0052 -0.07
        children [
          Box {
            size 0.02 0.004 0.02
          }
        ]
      }
      Pose {
        translation -0.31 0.0052 -0.13
        children [
          Box {
            size 0.02 0.004 0.02
          }
        ]
      }
      Pose {
        translation -0.31 0.0052 -0.19
        children [
          Box {
            size 0.02 0.004 0.02
          }
        ]
      }
      Pose {
        translation -0.31 0.0052 -0.25
        children [
          Box {
            size 0.02 0.004 0.02
          }
        ]
      }
      Pose {
        translation -0.31 0.0052 -0.31
        children [
          Box {
            size 0.02 0.004 0.02
          }
        ]
      }
      Pose {
        translation -0.25 0.0052 -0.01
        children [
          Box {
            size 0.02 0.004 0.02
          }
        ]
      }
      Pose {
        translation -0.25 0.0052 -0.07
        children [
          Box {
            size 0.02 0.004 0.02
          }
        ]
      }
      Pose {
        translation -0.25 0.0052 -0.13
        children [
          Box {
            size 0.02 0.004 0.02
          }
        ]
      }
      Pose {
        translation -0.25 0.0052 -0.19
        children [
          Box {
            size 0.02 0.004 0.02
          }
        ]
      }
      Pose {
        translation -0.25 0.0052 -0.25
        children [
          Box {
            size 0.02 0.004 0.02
          }
        ]
      }
      Pose {
        translation -0.25 0.0052 -0.31
        children [
          Box {
            size 0.02 0.004 0.02
          }
        ]
      }
      Pose {
        translation -0.19 0.0052 -0.01
        children [
          Box {
            size 0.02 0.004 0.02
          }
        ]
      }
      Pose {
        translation -0.19 0.0052 -0.07
        children [
          Box {
            size 0.02 0.004 0.02
          }
        ]
      }
      Pose {
        translation -0.19 0.0052 -0.13
        children [
          Box {
            size 0.02 0.004 0.02
          }
        ]
      }
      Pose {
        translation -0.19 0.0052 -0.19
        children [
          Box {
            size 0.02 0.004 0.02
          }
        ]
      }
      Pose {
        translation -0.19 0.0052 -0.25
        children [
          Box {
            size 0.02 0.004 0.02
          }
        ]
      }
      Pose {
        translation -0.19 0.0052 -0.31
        children [
          Box {
            size 0.02 0.004 0.02
          }
        ]
      }
      Pose {
        translation -0.13 0.0052 -0.01
        children [
          Box {
            size 0.02 0.004 0.02
          }
        ]
      }
      Pose {
        translation -0.13 0.0052 -0.07
        children [
          Box {
            size 0.02 0.004 0.02
          }
        ]
      }
      Pose {
        translation -0.13 0.0052 -0.13
        children [
          Box {
            size 0.02 0.004 0.02
          }
        ]
      }
      Pose {
        translation -0.13 0.0052 -0.19
        children [
          Box {
            size 0.02 0.004 0.02
          }
        ]
      }
      Pose {
        translation -0.13 0.0052 -0.25
        children [
          Box {
            size 0.02 0.004 0.02
          }
        ]
      }
      Pose {
        translation -0.13 0.0052 -0.31
        children [
          Box {
            size 0.02 0.004 0.02
          }
        ]
      }
      Pose {
        translation -0.07 0.0052 -0.01
        children [
          Box {
            size 0.02 0.004 0.02
          }
        ]
      }
      Pose {
        translation -0.07 0.0052 -0.07
        children [
          Box {
            size 0.02 0.004 0.02
          }
        ]
      }
      Pose {
        translation -0.07 0.0052 -0.13
        children [
          Box {
            size 0.02 0.004 0.02
          }
        ]
      }
      Pose {
        translation -0.07 0.0052 -0.19
        children [
          Box {
            size 0.02 0.004 0.02
          }
        ]
      }
      Pose {
        translation -0.07 0.0052 -0.25
        children [
          Box {
            size 0.02 0.004 0.02
          }
        ]
      }
      Pose {
        translation -0.07 0.0052 -0.31
        children [
          Box {
            size 0.02 0.004 0.02
          }
        ]
      }
      Pose {
        translation -0.01 0.0052 -0.01
        children [
          Box {
            size 0.02 0.004 0.02
          }
        ]
      }
      Pose {
        translation -0.01 0.0052 -0.07
        children [
          Box {
            size 0.02 0.004 0.02
          }
        ]
      }
      Pose {
        translation -0.01 0.0052 -0.13
        children [
          Box {
            size 0.02 0.004 0.02
          }
        ]
      }
      Pose {
        translation -0.01 0.0052 -0.19
        children [
          Box {
            size 0.02 0.004 0.02
          }
        ]
      }
      Pose {
        translation -0.01 0.0052 -0.25
        children [
          Box {
            size 0.02 0.004 0.02
          }
        ]
      }
      Pose {
        translation -0.01 0.0052 -0.31
        children [
          Box {
            size 0.02 0.004 0.02
          }
        ]
      }
      Pose {
        translation -0.500961 0.0033 -0.17
        rotation 0 0 -1 0
        children [
          Box {
            size 1 0.0034 0.34
          }
        ]
      }
    ]
  }
}
