#VRML_SIM R2025a utf8

EXTERNPROTO "https://raw.githubusercontent.com/cyberbotics/webots/R2025a/projects/objects/backgrounds/protos/TexturedBackground.proto"
EXTERNPROTO "https://raw.githubusercontent.com/cyberbotics/webots/R2025a/projects/objects/backgrounds/protos/TexturedBackgroundLight.proto"
EXTERNPROTO "https://raw.githubusercontent.com/cyberbotics/webots/R2025a/projects/objects/floors/protos/RectangleArena.proto"

WorldInfo {
  contactProperties [
    ContactProperties {
      material1 "rubber"
      material2 "parchment_paper"
      coulombFriction [
        0.4
      ]
    }
    ContactProperties {
      material1 "rubber"
      material2 "ground"
      coulombFriction [
        0.8
      ]
    }
    ContactProperties {
      material1 "rubber"
      material2 "whiteboard"
      coulombFriction [
        0.7
      ]
    }
    ContactProperties {
      material1 "rubber"
      material2 "bumpGround"
      coulombFriction [
        0.85
      ]
    }
  ]
}
Viewpoint {
  orientation -0.22621903483761696 0.3997686399970203 0.8882623389247513 1.054045364897764
  position -2.0667200369226086 -2.96126071140145 1.915006017319906
}
TexturedBackground {
}
TexturedBackgroundLight {
}
Viewpoint {
  orientation -0.2256052783179886 0.733251589159842 0.6414392920531368 1.148561532759604
  position -2.480124444647765 -1.7721924346661442 3.1127122535974543
}
TexturedBackground {
}
TexturedBackgroundLight {
  luminosity 0
}
RectangleArena {
  contactMaterial "parchment_paper"
  floorSize 3 3
}
DEF WAYPOINT_MARKER Solid {
  translation 0.3832 -0.0597 0.002
  children [
    Shape {
      appearance PBRAppearance {
        baseColor 1 0 0
        transparency 0.8
        roughness 1
        metalness 0
        emissiveColor 1 0 0
      }
      geometry Cylinder {
        height 1
        radius 0.03
      }
    }
  ]
}
DEF POLULU_ROBOT Robot {
  translation 0.33716282327597236 -0.07112186761893295 0.01574355062206762
  rotation 0.0460783514290906 0.04941446527079653 0.9977148872055477 1.74690081989568
  children [
    Display {
      width 230
    }
    InertialUnit {
      name "imu"
    }
    GPS {
    }
    Shape {
      appearance PBRAppearance {
        roughness 1
        metalness 0
      }
      geometry Mesh {
        url [
          "../../../Downloads/bodywithoutcaster.obj"
        ]
      }
      castShadows FALSE
      isPickable FALSE
    }
    BallJoint {
      jointParameters BallJointParameters {
        position -1362.5585616515762
        anchor 0 0.0404 -0.0096
      }
      jointParameters2 JointParameters {
        position 30.409872222704006
        axis 1 0 0
      }
      jointParameters3 JointParameters {
        position 22.81777275371977
        axis 0 1 0
      }
      endPoint Solid {
        translation -0.029379698610637217 0.06943829028636819 -0.015380678877151978
        rotation -0.25839169829499525 -0.26640436133516604 -0.9285808777450839 2.3572207839433834
        children [
          Shape {
            appearance PBRAppearance {
              roughness 1
              metalness 0
            }
            geometry Mesh {
              url [
                "../Models/caster.obj"
              ]
            }
            castShadows FALSE
            isPickable FALSE
          }
        ]
        name "caster"
        boundingObject Pose {
          translation 0 0.0404 -0.00963
          children [
            Sphere {
              radius 0.00635
              subdivision 3
            }
          ]
        }
        physics Physics {
        }
        linearVelocity 0.006685344180114801 -0.004237612270122752 0.0003053628649675977
        angularVelocity -1.287079043691012 -2.0411836849277805 -3.518368541171094
      }
    }
    HingeJoint {
      jointParameters HingeJointParameters {
        position 2290.1458143721993
      }
      device [
        RotationalMotor {
          name "LeftMotor"
          maxVelocity 75.4
        }
      ]
      endPoint Solid {
        translation 0.0414994745986966 0.0003628235042695337 -7.807044010063277e-05
        rotation -0.7074991342282526 -0.06771382604324108 0.7034627302344162 3.01300199415802
        children [
          DEF wheel Shape {
            appearance PBRAppearance {
              roughness 1
              metalness 0
            }
            geometry Cylinder {
              height 0.0068
              radius 0.016
              subdivision 500
            }
            castShadows FALSE
            isPickable FALSE
          }
        ]
        contactMaterial "rubber"
        boundingObject USE wheel
        physics Physics {
        }
        linearVelocity -4.432038082366616e-06 -2.6920063667430446e-06 1.0934683412576281e-05
        angularVelocity -0.0002209253856554762 -0.0003248448533314617 0.00010708756245073398
      }
    }
    HingeJoint {
      jointParameters HingeJointParameters {
        position 3166.5080691786334
      }
      device [
        DEF RightMotor RotationalMotor {
          name "RightMotor"
          maxVelocity 75.4
        }
      ]
      endPoint Solid {
        translation -0.04149868078943603 0.0003674797960833964 0.000373255691971593
        rotation 0.10769441376474698 -0.9882355099149043 0.10859323269475235 4.705695400293508
        children [
          USE wheel
        ]
        contactMaterial "rubber"
        boundingObject USE wheel
        physics Physics {
        }
        linearVelocity -5.9135123051455e-06 1.0608011669272405e-05 3.678688299344236e-05
        angularVelocity -0.00022087177696281769 -0.0003248389329734092 0.00010718309576486642
      }
    }
  ]
  boundingObject Pose {
    translation 0 0 0.0025
    children [
      Cylinder {
        height 0.0266
        radius 0.0484
        subdivision 50
      }
    ]
  }
  physics Physics {
    mass 0.158
    centerOfMass [
      0 0 0
    ]
  }
  controller "autonomous_navigation"
  supervisor TRUE
  linearVelocity -5.165298531812558e-06 3.983179586224693e-06 2.39888508428447e-05
  angularVelocity -0.00022070264976977382 -0.00032480751601685797 0.00010659900812714993
}
Solid {
  translation -0.34 1.01 5.00225e-06
  rotation 0.5773509358554485 0.5773489358556708 0.5773509358554485 2.0944
  children [
    DEF obstacle Shape {
      appearance PBRAppearance {
        baseColor 0 0 0
        roughness 1
        metalness 0
      }
      geometry Mesh {
        url [
          "../Models/ramp.obj"
        ]
      }
    }
  ]
  name "ramp"
  contactMaterial "whiteboard"
  boundingObject Group {
    children [
      Pose {
        translation -0.590961 0.033 0
        rotation 0 0 1 0.3321694619948667
        children [
          Box {
            size 0.76 0.1 0.28
          }
        ]
      }
      Pose {
        translation -0.01 0.1024 0
        children [
          Box {
            size 0.25 0.25 0.31
          }
        ]
      }
      Pose {
        translation -0.108 -0.2061 0
        children [
          Capsule {
            height 0.4
            radius 0.434
            subdivision 500
          }
        ]
      }
    ]
  }
}
Solid {
  translation 0.58 0.99 3.36042e-06
  rotation 0.5773509358554485 0.5773489358556708 0.5773509358554485 2.0944
  children [
    DEF bump Shape {
      appearance PBRAppearance {
        baseColor 0 0 0
        roughness 1
        metalness 0
      }
      geometry Mesh {
        url [
          "../../../Downloads/bump.obj"
        ]
      }
    }
  ]
  name "bump"
  contactMaterial "bumpGround"
  boundingObject Group {
    children [
      Pose {
        translation -0.97 0.0052 -0.01
        children [
          Box {
            size 0.02 0.004 0.02
          }
        ]
      }
      Pose {
        translation -0.97 0.0052 -0.07
        children [
          Box {
            size 0.02 0.004 0.02
          }
        ]
      }
      Pose {
        translation -0.97 0.0052 -0.13
        children [
          Box {
            size 0.02 0.004 0.02
          }
        ]
      }
      Pose {
        translation -0.97 0.0052 -0.19
        children [
          Box {
            size 0.02 0.004 0.02
          }
        ]
      }
      Pose {
        translation -0.97 0.0052 -0.25
        children [
          Box {
            size 0.02 0.004 0.02
          }
        ]
      }
      Pose {
        translation -0.97 0.0052 -0.31
        children [
          Box {
            size 0.02 0.004 0.02
          }
        ]
      }
      Pose {
        translation -0.91 0.0052 -0.01
        children [
          Box {
            size 0.02 0.004 0.02
          }
        ]
      }
      Pose {
        translation -0.91 0.0052 -0.07
        children [
          Box {
            size 0.02 0.004 0.02
          }
        ]
      }
      Pose {
        translation -0.91 0.0052 -0.13
        children [
          Box {
            size 0.02 0.004 0.02
          }
        ]
      }
      Pose {
        translation -0.91 0.0052 -0.19
        children [
          Box {
            size 0.02 0.004 0.02
          }
        ]
      }
      Pose {
        translation -0.91 0.0052 -0.25
        children [
          Box {
            size 0.02 0.004 0.02
          }
        ]
      }
      Pose {
        translation -0.91 0.0052 -0.31
        children [
          Box {
            size 0.02 0.004 0.02
          }
        ]
      }
      Pose {
        translation -0.85 0.0052 -0.01
        children [
          Box {
            size 0.02 0.004 0.02
          }
        ]
      }
      Pose {
        translation -0.85 0.0052 -0.07
        children [
          Box {
            size 0.02 0.004 0.02
          }
        ]
      }
      Pose {
        translation -0.85 0.0052 -0.13
        children [
          Box {
            size 0.02 0.004 0.02
          }
        ]
      }
      Pose {
        translation -0.85 0.0052 -0.19
        children [
          Box {
            size 0.02 0.004 0.02
          }
        ]
      }
      Pose {
        translation -0.85 0.0052 -0.25
        children [
          Box {
            size 0.02 0.004 0.02
          }
        ]
      }
      Pose {
        translation -0.85 0.0052 -0.31
        children [
          Box {
            size 0.02 0.004 0.02
          }
        ]
      }
      Pose {
        translation -0.79 0.0052 -0.01
        children [
          Box {
            size 0.02 0.004 0.02
          }
        ]
      }
      Pose {
        translation -0.79 0.0052 -0.07
        children [
          Box {
            size 0.02 0.004 0.02
          }
        ]
      }
      Pose {
        translation -0.79 0.0052 -0.13
        children [
          Box {
            size 0.02 0.004 0.02
          }
        ]
      }
      Pose {
        translation -0.79 0.0052 -0.19
        children [
          Box {
            size 0.02 0.004 0.02
          }
        ]
      }
      Pose {
        translation -0.79 0.0052 -0.25
        children [
          Box {
            size 0.02 0.004 0.02
          }
        ]
      }
      Pose {
        translation -0.79 0.0052 -0.31
        children [
          Box {
            size 0.02 0.004 0.02
          }
        ]
      }
      Pose {
        translation -0.73 0.0052 -0.01
        children [
          Box {
            size 0.02 0.004 0.02
          }
        ]
      }
      Pose {
        translation -0.73 0.0052 -0.07
        children [
          Box {
            size 0.02 0.004 0.02
          }
        ]
      }
      Pose {
        translation -0.73 0.0052 -0.13
        children [
          Box {
            size 0.02 0.004 0.02
          }
        ]
      }
      Pose {
        translation -0.73 0.0052 -0.19
        children [
          Box {
            size 0.02 0.004 0.02
          }
        ]
      }
      Pose {
        translation -0.73 0.0052 -0.25
        children [
          Box {
            size 0.02 0.004 0.02
          }
        ]
      }
      Pose {
        translation -0.73 0.0052 -0.31
        children [
          Box {
            size 0.02 0.004 0.02
          }
        ]
      }
      Pose {
        translation -0.67 0.0052 -0.01
        children [
          Box {
            size 0.02 0.004 0.02
          }
        ]
      }
      Pose {
        translation -0.67 0.0052 -0.07
        children [
          Box {
            size 0.02 0.004 0.02
          }
        ]
      }
      Pose {
        translation -0.67 0.0052 -0.13
        children [
          Box {
            size 0.02 0.004 0.02
          }
        ]
      }
      Pose {
        translation -0.67 0.0052 -0.19
        children [
          Box {
            size 0.02 0.004 0.02
          }
        ]
      }
      Pose {
        translation -0.67 0.0052 -0.25
        children [
          Box {
            size 0.02 0.004 0.02
          }
        ]
      }
      Pose {
        translation -0.67 0.0052 -0.31
        children [
          Box {
            size 0.02 0.004 0.02
          }
        ]
      }
      Pose {
        translation -0.61 0.0052 -0.01
        children [
          Box {
            size 0.02 0.004 0.02
          }
        ]
      }
      Pose {
        translation -0.61 0.0052 -0.07
        children [
          Box {
            size 0.02 0.004 0.02
          }
        ]
      }
      Pose {
        translation -0.61 0.0052 -0.13
        children [
          Box {
            size 0.02 0.004 0.02
          }
        ]
      }
      Pose {
        translation -0.61 0.0052 -0.19
        children [
          Box {
            size 0.02 0.004 0.02
          }
        ]
      }
      Pose {
        translation -0.61 0.0052 -0.25
        children [
          Box {
            size 0.02 0.004 0.02
          }
        ]
      }
      Pose {
        translation -0.61 0.0052 -0.31
        children [
          Box {
            size 0.02 0.004 0.02
          }
        ]
      }
      Pose {
        translation -0.55 0.0052 -0.01
        children [
          Box {
            size 0.02 0.004 0.02
          }
        ]
      }
      Pose {
        translation -0.55 0.0052 -0.07
        children [
          Box {
            size 0.02 0.004 0.02
          }
        ]
      }
      Pose {
        translation -0.55 0.0052 -0.13
        children [
          Box {
            size 0.02 0.004 0.02
          }
        ]
      }
      Pose {
        translation -0.55 0.0052 -0.19
        children [
          Box {
            size 0.02 0.004 0.02
          }
        ]
      }
      Pose {
        translation -0.55 0.0052 -0.25
        children [
          Box {
            size 0.02 0.004 0.02
          }
        ]
      }
      Pose {
        translation -0.55 0.0052 -0.31
        children [
          Box {
            size 0.02 0.004 0.02
          }
        ]
      }
      Pose {
        translation -0.49 0.0052 -0.01
        children [
          Box {
            size 0.02 0.004 0.02
          }
        ]
      }
      Pose {
        translation -0.49 0.0052 -0.07
        children [
          Box {
            size 0.02 0.004 0.02
          }
        ]
      }
      Pose {
        translation -0.49 0.0052 -0.13
        children [
          Box {
            size 0.02 0.004 0.02
          }
        ]
      }
      Pose {
        translation -0.49 0.0052 -0.19
        children [
          Box {
            size 0.02 0.004 0.02
          }
        ]
      }
      Pose {
        translation -0.49 0.0052 -0.25
        children [
          Box {
            size 0.02 0.004 0.02
          }
        ]
      }
      Pose {
        translation -0.49 0.0052 -0.31
        children [
          Box {
            size 0.02 0.004 0.02
          }
        ]
      }
      Pose {
        translation -0.43 0.0052 -0.01
        children [
          Box {
            size 0.02 0.004 0.02
          }
        ]
      }
      Pose {
        translation -0.43 0.0052 -0.07
        children [
          Box {
            size 0.02 0.004 0.02
          }
        ]
      }
      Pose {
        translation -0.43 0.0052 -0.13
        children [
          Box {
            size 0.02 0.004 0.02
          }
        ]
      }
      Pose {
        translation -0.43 0.0052 -0.19
        children [
          Box {
            size 0.02 0.004 0.02
          }
        ]
      }
      Pose {
        translation -0.43 0.0052 -0.25
        children [
          Box {
            size 0.02 0.004 0.02
          }
        ]
      }
      Pose {
        translation -0.43 0.0052 -0.31
        children [
          Box {
            size 0.02 0.004 0.02
          }
        ]
      }
      Pose {
        translation -0.37 0.0052 -0.01
        children [
          Box {
            size 0.02 0.004 0.02
          }
        ]
      }
      Pose {
        translation -0.37 0.0052 -0.07
        children [
          Box {
            size 0.02 0.004 0.02
          }
        ]
      }
      Pose {
        translation -0.37 0.0052 -0.13
        children [
          Box {
            size 0.02 0.004 0.02
          }
        ]
      }
      Pose {
        translation -0.37 0.0052 -0.19
        children [
          Box {
            size 0.02 0.004 0.02
          }
        ]
      }
      Pose {
        translation -0.37 0.0052 -0.25
        children [
          Box {
            size 0.02 0.004 0.02
          }
        ]
      }
      Pose {
        translation -0.37 0.0052 -0.31
        children [
          Box {
            size 0.02 0.004 0.02
          }
        ]
      }
      Pose {
        translation -0.31 0.0052 -0.01
        children [
          Box {
            size 0.02 0.004 0.02
          }
        ]
      }
      Pose {
        translation -0.31 0.0052 -0.07
        children [
          Box {
            size 0.02 0.004 0.02
          }
        ]
      }
      Pose {
        translation -0.31 0.0052 -0.13
        children [
          Box {
            size 0.02 0.004 0.02
          }
        ]
      }
      Pose {
        translation -0.31 0.0052 -0.19
        children [
          Box {
            size 0.02 0.004 0.02
          }
        ]
      }
      Pose {
        translation -0.31 0.0052 -0.25
        children [
          Box {
            size 0.02 0.004 0.02
          }
        ]
      }
      Pose {
        translation -0.31 0.0052 -0.31
        children [
          Box {
            size 0.02 0.004 0.02
          }
        ]
      }
      Pose {
        translation -0.25 0.0052 -0.01
        children [
          Box {
            size 0.02 0.004 0.02
          }
        ]
      }
      Pose {
        translation -0.25 0.0052 -0.07
        children [
          Box {
            size 0.02 0.004 0.02
          }
        ]
      }
      Pose {
        translation -0.25 0.0052 -0.13
        children [
          Box {
            size 0.02 0.004 0.02
          }
        ]
      }
      Pose {
        translation -0.25 0.0052 -0.19
        children [
          Box {
            size 0.02 0.004 0.02
          }
        ]
      }
      Pose {
        translation -0.25 0.0052 -0.25
        children [
          Box {
            size 0.02 0.004 0.02
          }
        ]
      }
      Pose {
        translation -0.25 0.0052 -0.31
        children [
          Box {
            size 0.02 0.004 0.02
          }
        ]
      }
      Pose {
        translation -0.19 0.0052 -0.01
        children [
          Box {
            size 0.02 0.004 0.02
          }
        ]
      }
      Pose {
        translation -0.19 0.0052 -0.07
        children [
          Box {
            size 0.02 0.004 0.02
          }
        ]
      }
      Pose {
        translation -0.19 0.0052 -0.13
        children [
          Box {
            size 0.02 0.004 0.02
          }
        ]
      }
      Pose {
        translation -0.19 0.0052 -0.19
        children [
          Box {
            size 0.02 0.004 0.02
          }
        ]
      }
      Pose {
        translation -0.19 0.0052 -0.25
        children [
          Box {
            size 0.02 0.004 0.02
          }
        ]
      }
      Pose {
        translation -0.19 0.0052 -0.31
        children [
          Box {
            size 0.02 0.004 0.02
          }
        ]
      }
      Pose {
        translation -0.13 0.0052 -0.01
        children [
          Box {
            size 0.02 0.004 0.02
          }
        ]
      }
      Pose {
        translation -0.13 0.0052 -0.07
        children [
          Box {
            size 0.02 0.004 0.02
          }
        ]
      }
      Pose {
        translation -0.13 0.0052 -0.13
        children [
          Box {
            size 0.02 0.004 0.02
          }
        ]
      }
      Pose {
        translation -0.13 0.0052 -0.19
        children [
          Box {
            size 0.02 0.004 0.02
          }
        ]
      }
      Pose {
        translation -0.13 0.0052 -0.25
        children [
          Box {
            size 0.02 0.004 0.02
          }
        ]
      }
      Pose {
        translation -0.13 0.0052 -0.31
        children [
          Box {
            size 0.02 0.004 0.02
          }
        ]
      }
      Pose {
        translation -0.07 0.0052 -0.01
        children [
          Box {
            size 0.02 0.004 0.02
          }
        ]
      }
      Pose {
        translation -0.07 0.0052 -0.07
        children [
          Box {
            size 0.02 0.004 0.02
          }
        ]
      }
      Pose {
        translation -0.07 0.0052 -0.13
        children [
          Box {
            size 0.02 0.004 0.02
          }
        ]
      }
      Pose {
        translation -0.07 0.0052 -0.19
        children [
          Box {
            size 0.02 0.004 0.02
          }
        ]
      }
      Pose {
        translation -0.07 0.0052 -0.25
        children [
          Box {
            size 0.02 0.004 0.02
          }
        ]
      }
      Pose {
        translation -0.07 0.0052 -0.31
        children [
          Box {
            size 0.02 0.004 0.02
          }
        ]
      }
      Pose {
        translation -0.01 0.0052 -0.01
        children [
          Box {
            size 0.02 0.004 0.02
          }
        ]
      }
      Pose {
        translation -0.01 0.0052 -0.07
        children [
          Box {
            size 0.02 0.004 0.02
          }
        ]
      }
      Pose {
        translation -0.01 0.0052 -0.13
        children [
          Box {
            size 0.02 0.004 0.02
          }
        ]
      }
      Pose {
        translation -0.01 0.0052 -0.19
        children [
          Box {
            size 0.02 0.004 0.02
          }
        ]
      }
      Pose {
        translation -0.01 0.0052 -0.25
        children [
          Box {
            size 0.02 0.004 0.02
          }
        ]
      }
      Pose {
        translation -0.01 0.0052 -0.31
        children [
          Box {
            size 0.02 0.004 0.02
          }
        ]
      }
      Pose {
        translation -0.500961 0.0033 -0.17
        rotation 0 0 -1 0
        children [
          Box {
            size 1 0.0034 0.34
          }
        ]
      }
    ]
  }
}
