#VRML_SIM R2025a utf8

EXTERNPROTO "https://raw.githubusercontent.com/cyberbotics/webots/R2025a/projects/objects/backgrounds/protos/TexturedBackground.proto"
EXTERNPROTO "https://raw.githubusercontent.com/cyberbotics/webots/R2025a/projects/objects/backgrounds/protos/TexturedBackgroundLight.proto"
EXTERNPROTO "https://raw.githubusercontent.com/cyberbotics/webots/R2025a/projects/objects/floors/protos/RectangleArena.proto"

WorldInfo {
  contactProperties [
    ContactProperties {
      material1 "rubber"
      material2 "whiteboard"
      coulombFriction [
        0.7
      ]
    }
    ContactProperties {
      material1 "rubber"
      material2 "bumpGround"
      coulombFriction [
        0.85
      ]
    }
  ]
}
Viewpoint {
  orientation -0.22621903483761696 0.3997686399970203 0.8882623389247513 1.054045364897764
  position -2.0667200369226086 -2.96126071140145 1.915006017319906
}
TexturedBackground {
}
TexturedBackgroundLight {
}
Viewpoint {
  orientation -0.3429486747414967 0.1964663925381598 0.9185788823482132 2.372959839465537
  position 2.696318191055476 -2.6755841120195223 2.899798334626136
}
TexturedBackground {
}
TexturedBackgroundLight {
  luminosity 0
}
RectangleArena {
  floorSize 3 3
}
DEF WAYPOINT_MARKER Solid {
  translation 0.3445 -0.0912 0.002
  children [
    Shape {
      appearance PBRAppearance {
        baseColor 1 0 0
        transparency 0.8
        roughness 1
        metalness 0
        emissiveColor 1 0 0
      }
      geometry Cylinder {
        height 1
        radius 0.03
      }
    }
  ]
}
DEF POLULU_ROBOT Robot {
  translation 0.29720840968619616 -0.09087102795396368 0.07772544887601816
  rotation -0.014376187689614657 0.05744565953803831 0.9982451209135724 1.6178764746288998
  children [
    Display {
      width 230
    }
    InertialUnit {
      name "imu"
    }
    GPS {
    }
    Shape {
      appearance PBRAppearance {
        roughness 1
        metalness 0
      }
      geometry Mesh {
        url [
          "../../../Downloads/bodywithoutcaster.obj"
        ]
      }
      castShadows FALSE
      isPickable FALSE
    }
    BallJoint {
      jointParameters BallJointParameters {
        position -1482.5714183150876
        anchor 0 0.0404 -0.0096
      }
      jointParameters2 JointParameters {
        position 25.415334682821925
        axis 1 0 0
      }
      jointParameters3 JointParameters {
        position -34.15900233936226
        axis 0 1 0
      }
      endPoint Solid {
        translation 0.03888124554261488 0.04929087957505052 -0.021665659227239287
        rotation -0.20491602778828005 -0.2229853082012392 -0.9530409088186462 -1.8461557368282406
        children [
          Shape {
            appearance PBRAppearance {
              roughness 1
              metalness 0
            }
            geometry Mesh {
              url [
                "../Models/caster.obj"
              ]
            }
            castShadows FALSE
            isPickable FALSE
          }
        ]
        name "caster"
        boundingObject Pose {
          translation 0 0.0404 -0.00963
          children [
            Sphere {
              radius 0.00635
              subdivision 3
            }
          ]
        }
        physics Physics {
        }
        linearVelocity -0.00010282456187906329 -5.8515705624181946e-05 3.89117042820675e-06
        angularVelocity 0.009012641710944336 -0.04375247744951308 -0.42004288813501744
      }
    }
    HingeJoint {
      jointParameters HingeJointParameters {
        position 1977.283804306017
      }
      device [
        RotationalMotor {
          name "LeftMotor"
          maxVelocity 75.4
        }
      ]
      endPoint Solid {
        translation 0.0414994745986966 0.0001731818580558631 0.0003282437096247994
        rotation -0.596275673183031 -0.5440199668794777 0.5903368506256198 2.145489028772377
        children [
          DEF wheel Shape {
            appearance PBRAppearance {
              roughness 1
              metalness 0
            }
            geometry Cylinder {
              height 0.0068
              radius 0.016
              subdivision 500
            }
            castShadows FALSE
            isPickable FALSE
          }
        ]
        contactMaterial "rubber"
        boundingObject USE wheel
        physics Physics {
        }
        linearVelocity 9.333118648807964e-08 1.8645542739811475e-07 -1.3344943000797319e-08
        angularVelocity -3.325314355705905e-07 5.85156011097653e-06 -3.182795307790065e-07
      }
    }
    HingeJoint {
      jointParameters HingeJointParameters {
        position 2591.262364140686
      }
      device [
        DEF RightMotor RotationalMotor {
          name "RightMotor"
          maxVelocity 75.4
        }
      ]
      endPoint Solid {
        translation -0.041498680789435985 -0.00046959263999656997 -0.00023204302312230488
        rotation -0.6952199741146141 -0.19627410074532592 -0.6914807770059043 3.5291591018629913
        children [
          USE wheel
        ]
        contactMaterial "rubber"
        boundingObject USE wheel
        physics Physics {
        }
        linearVelocity 9.891200616546765e-08 1.8692341842218342e-07 -1.2254481772931154e-08
        angularVelocity -3.323026713395252e-07 5.846673265761775e-06 -3.179345307519318e-07
      }
    }
  ]
  boundingObject Pose {
    translation 0 0 0.0025
    children [
      Cylinder {
        height 0.0266
        radius 0.0484
        subdivision 50
      }
    ]
  }
  physics Physics {
    mass 0.158
    centerOfMass [
      0 0 0
    ]
  }
  controller "autonomous_navigation"
  supervisor TRUE
  linearVelocity 9.596027021864692e-08 1.868298486255912e-07 -1.1950169461578057e-08
  angularVelocity -3.3245232257684473e-07 5.849882315615582e-06 -3.181669460467665e-07
}
Solid {
  translation -0.34 0.82 4.02622e-06
  rotation 0.5773509358554485 0.5773489358556708 0.5773509358554485 2.0944
  children [
    DEF obstacle Shape {
      appearance PBRAppearance {
        baseColor 0 0 0
        roughness 1
        metalness 0
      }
      geometry Mesh {
        url [
          "../Models/ramp.obj"
        ]
      }
    }
  ]
  name "ramp"
  contactMaterial "whiteboard"
  boundingObject Group {
    children [
      Pose {
        translation -0.590961 0.033 0
        rotation 0 0 1 0.3321694619948667
        children [
          Box {
            size 0.76 0.1 0.28
          }
        ]
      }
      Pose {
        translation -0.01 0.1024 0
        children [
          Box {
            size 0.25 0.25 0.31
          }
        ]
      }
      Pose {
        translation -0.108 -0.2061 0
        children [
          Capsule {
            height 0.4
            radius 0.434
            subdivision 500
          }
        ]
      }
    ]
  }
}
Solid {
  translation 1.10006 -0.423004 0.0834047
  rotation 0.5644111945626767 0.6026425263832473 0.5641471340410668 2.057392013284558
  children [
    DEF obstacle Shape {
      appearance PBRAppearance {
        baseColor 0 0 0
        roughness 1
        metalness 0
      }
      geometry Mesh {
        url [
          "../Models/ramp.obj"
        ]
      }
    }
  ]
  name "example"
  contactMaterial "whiteboard"
  boundingObject Group {
    children [
      Pose {
        translation -0.363 -0.0003 3.8464e-08
        rotation -0.577349935856137 -0.577349935856137 -0.5773509358560258 2.094395307179586
        children [
          Plane {
            size 0.305 0.95
          }
        ]
      }
      Pose {
        translation -0.01 0.114 0
        children [
          Box {
            size 0.245 0.228 0.31
          }
        ]
      }
    ]
  }
}
Solid {
  translation 0.0600558 -0.423063 0.0839582
  rotation 0.5644111945626767 0.6026425263832473 0.5641471340410668 2.057392013284558
  children [
    DEF obstacle Shape {
      appearance PBRAppearance {
        baseColor 0 0 0
        roughness 1
        metalness 0
      }
      geometry Mesh {
        url [
          "../Models/ramp.obj"
        ]
      }
    }
  ]
  name "angledRamp"
  contactMaterial "whiteboard"
  boundingObject Group {
    children [
      Pose {
        translation -0.363 -0.0003 3.8464e-08
        rotation -0.577349935856137 -0.577349935856137 -0.5773509358560258 2.094395307179586
        children [
          Plane {
            size 0.305 0.95
          }
        ]
      }
      Pose {
        translation -0.01 0.114 0
        children [
          Box {
            size 0.245 0.228 0.31
          }
        ]
      }
    ]
  }
}
Solid {
  translation 0.0500661 -1.10568 0.0823988
  rotation 0.5644239799881435 0.6026550701680317 0.5641209420107612 2.057315308074302
  children [
    Shape {
      appearance PBRAppearance {
        baseColor 0 0 0
        roughness 1
        metalness 0
      }
      geometry Mesh {
        url [
          "../../../Downloads/stepping_stone.obj"
        ]
      }
    }
  ]
  name "steppingStone"
  contactMaterial ""
  boundingObject Group {
    children [
      Pose {
        children [
          Box {
            size 0.3 0.05 0.305
          }
        ]
      }
    ]
  }
}
Solid {
  translation 0.58 0.99 3.36042e-06
  rotation 0.5773509358554485 0.5773489358556708 0.5773509358554485 2.0944
  children [
    DEF bump Shape {
      appearance PBRAppearance {
        baseColor 0 0 0
        roughness 1
        metalness 0
      }
      geometry Mesh {
        url [
          "../../../Downloads/bump.obj"
        ]
      }
    }
  ]
  name "bump"
  contactMaterial "bumpGround"
  boundingObject Group {
    children [
      Pose {
        translation -0.97 0.0052 -0.01
        children [
          Box {
            size 0.02 0.004 0.02
          }
        ]
      }
      Pose {
        translation -0.97 0.0052 -0.07
        children [
          Box {
            size 0.02 0.004 0.02
          }
        ]
      }
      Pose {
        translation -0.97 0.0052 -0.13
        children [
          Box {
            size 0.02 0.004 0.02
          }
        ]
      }
      Pose {
        translation -0.97 0.0052 -0.19
        children [
          Box {
            size 0.02 0.004 0.02
          }
        ]
      }
      Pose {
        translation -0.97 0.0052 -0.25
        children [
          Box {
            size 0.02 0.004 0.02
          }
        ]
      }
      Pose {
        translation -0.97 0.0052 -0.31
        children [
          Box {
            size 0.02 0.004 0.02
          }
        ]
      }
      Pose {
        translation -0.91 0.0052 -0.01
        children [
          Box {
            size 0.02 0.004 0.02
          }
        ]
      }
      Pose {
        translation -0.91 0.0052 -0.07
        children [
          Box {
            size 0.02 0.004 0.02
          }
        ]
      }
      Pose {
        translation -0.91 0.0052 -0.13
        children [
          Box {
            size 0.02 0.004 0.02
          }
        ]
      }
      Pose {
        translation -0.91 0.0052 -0.19
        children [
          Box {
            size 0.02 0.004 0.02
          }
        ]
      }
      Pose {
        translation -0.91 0.0052 -0.25
        children [
          Box {
            size 0.02 0.004 0.02
          }
        ]
      }
      Pose {
        translation -0.91 0.0052 -0.31
        children [
          Box {
            size 0.02 0.004 0.02
          }
        ]
      }
      Pose {
        translation -0.85 0.0052 -0.01
        children [
          Box {
            size 0.02 0.004 0.02
          }
        ]
      }
      Pose {
        translation -0.85 0.0052 -0.07
        children [
          Box {
            size 0.02 0.004 0.02
          }
        ]
      }
      Pose {
        translation -0.85 0.0052 -0.13
        children [
          Box {
            size 0.02 0.004 0.02
          }
        ]
      }
      Pose {
        translation -0.85 0.0052 -0.19
        children [
          Box {
            size 0.02 0.004 0.02
          }
        ]
      }
      Pose {
        translation -0.85 0.0052 -0.25
        children [
          Box {
            size 0.02 0.004 0.02
          }
        ]
      }
      Pose {
        translation -0.85 0.0052 -0.31
        children [
          Box {
            size 0.02 0.004 0.02
          }
        ]
      }
      Pose {
        translation -0.79 0.0052 -0.01
        children [
          Box {
            size 0.02 0.004 0.02
          }
        ]
      }
      Pose {
        translation -0.79 0.0052 -0.07
        children [
          Box {
            size 0.02 0.004 0.02
          }
        ]
      }
      Pose {
        translation -0.79 0.0052 -0.13
        children [
          Box {
            size 0.02 0.004 0.02
          }
        ]
      }
      Pose {
        translation -0.79 0.0052 -0.19
        children [
          Box {
            size 0.02 0.004 0.02
          }
        ]
      }
      Pose {
        translation -0.79 0.0052 -0.25
        children [
          Box {
            size 0.02 0.004 0.02
          }
        ]
      }
      Pose {
        translation -0.79 0.0052 -0.31
        children [
          Box {
            size 0.02 0.004 0.02
          }
        ]
      }
      Pose {
        translation -0.73 0.0052 -0.01
        children [
          Box {
            size 0.02 0.004 0.02
          }
        ]
      }
      Pose {
        translation -0.73 0.0052 -0.07
        children [
          Box {
            size 0.02 0.004 0.02
          }
        ]
      }
      Pose {
        translation -0.73 0.0052 -0.13
        children [
          Box {
            size 0.02 0.004 0.02
          }
        ]
      }
      Pose {
        translation -0.73 0.0052 -0.19
        children [
          Box {
            size 0.02 0.004 0.02
          }
        ]
      }
      Pose {
        translation -0.73 0.0052 -0.25
        children [
          Box {
            size 0.02 0.004 0.02
          }
        ]
      }
      Pose {
        translation -0.73 0.0052 -0.31
        children [
          Box {
            size 0.02 0.004 0.02
          }
        ]
      }
      Pose {
        translation -0.67 0.0052 -0.01
        children [
          Box {
            size 0.02 0.004 0.02
          }
        ]
      }
      Pose {
        translation -0.67 0.0052 -0.07
        children [
          Box {
            size 0.02 0.004 0.02
          }
        ]
      }
      Pose {
        translation -0.67 0.0052 -0.13
        children [
          Box {
            size 0.02 0.004 0.02
          }
        ]
      }
      Pose {
        translation -0.67 0.0052 -0.19
        children [
          Box {
            size 0.02 0.004 0.02
          }
        ]
      }
      Pose {
        translation -0.67 0.0052 -0.25
        children [
          Box {
            size 0.02 0.004 0.02
          }
        ]
      }
      Pose {
        translation -0.67 0.0052 -0.31
        children [
          Box {
            size 0.02 0.004 0.02
          }
        ]
      }
      Pose {
        translation -0.61 0.0052 -0.01
        children [
          Box {
            size 0.02 0.004 0.02
          }
        ]
      }
      Pose {
        translation -0.61 0.0052 -0.07
        children [
          Box {
            size 0.02 0.004 0.02
          }
        ]
      }
      Pose {
        translation -0.61 0.0052 -0.13
        children [
          Box {
            size 0.02 0.004 0.02
          }
        ]
      }
      Pose {
        translation -0.61 0.0052 -0.19
        children [
          Box {
            size 0.02 0.004 0.02
          }
        ]
      }
      Pose {
        translation -0.61 0.0052 -0.25
        children [
          Box {
            size 0.02 0.004 0.02
          }
        ]
      }
      Pose {
        translation -0.61 0.0052 -0.31
        children [
          Box {
            size 0.02 0.004 0.02
          }
        ]
      }
      Pose {
        translation -0.55 0.0052 -0.01
        children [
          Box {
            size 0.02 0.004 0.02
          }
        ]
      }
      Pose {
        translation -0.55 0.0052 -0.07
        children [
          Box {
            size 0.02 0.004 0.02
          }
        ]
      }
      Pose {
        translation -0.55 0.0052 -0.13
        children [
          Box {
            size 0.02 0.004 0.02
          }
        ]
      }
      Pose {
        translation -0.55 0.0052 -0.19
        children [
          Box {
            size 0.02 0.004 0.02
          }
        ]
      }
      Pose {
        translation -0.55 0.0052 -0.25
        children [
          Box {
            size 0.02 0.004 0.02
          }
        ]
      }
      Pose {
        translation -0.55 0.0052 -0.31
        children [
          Box {
            size 0.02 0.004 0.02
          }
        ]
      }
      Pose {
        translation -0.49 0.0052 -0.01
        children [
          Box {
            size 0.02 0.004 0.02
          }
        ]
      }
      Pose {
        translation -0.49 0.0052 -0.07
        children [
          Box {
            size 0.02 0.004 0.02
          }
        ]
      }
      Pose {
        translation -0.49 0.0052 -0.13
        children [
          Box {
            size 0.02 0.004 0.02
          }
        ]
      }
      Pose {
        translation -0.49 0.0052 -0.19
        children [
          Box {
            size 0.02 0.004 0.02
          }
        ]
      }
      Pose {
        translation -0.49 0.0052 -0.25
        children [
          Box {
            size 0.02 0.004 0.02
          }
        ]
      }
      Pose {
        translation -0.49 0.0052 -0.31
        children [
          Box {
            size 0.02 0.004 0.02
          }
        ]
      }
      Pose {
        translation -0.43 0.0052 -0.01
        children [
          Box {
            size 0.02 0.004 0.02
          }
        ]
      }
      Pose {
        translation -0.43 0.0052 -0.07
        children [
          Box {
            size 0.02 0.004 0.02
          }
        ]
      }
      Pose {
        translation -0.43 0.0052 -0.13
        children [
          Box {
            size 0.02 0.004 0.02
          }
        ]
      }
      Pose {
        translation -0.43 0.0052 -0.19
        children [
          Box {
            size 0.02 0.004 0.02
          }
        ]
      }
      Pose {
        translation -0.43 0.0052 -0.25
        children [
          Box {
            size 0.02 0.004 0.02
          }
        ]
      }
      Pose {
        translation -0.43 0.0052 -0.31
        children [
          Box {
            size 0.02 0.004 0.02
          }
        ]
      }
      Pose {
        translation -0.37 0.0052 -0.01
        children [
          Box {
            size 0.02 0.004 0.02
          }
        ]
      }
      Pose {
        translation -0.37 0.0052 -0.07
        children [
          Box {
            size 0.02 0.004 0.02
          }
        ]
      }
      Pose {
        translation -0.37 0.0052 -0.13
        children [
          Box {
            size 0.02 0.004 0.02
          }
        ]
      }
      Pose {
        translation -0.37 0.0052 -0.19
        children [
          Box {
            size 0.02 0.004 0.02
          }
        ]
      }
      Pose {
        translation -0.37 0.0052 -0.25
        children [
          Box {
            size 0.02 0.004 0.02
          }
        ]
      }
      Pose {
        translation -0.37 0.0052 -0.31
        children [
          Box {
            size 0.02 0.004 0.02
          }
        ]
      }
      Pose {
        translation -0.31 0.0052 -0.01
        children [
          Box {
            size 0.02 0.004 0.02
          }
        ]
      }
      Pose {
        translation -0.31 0.0052 -0.07
        children [
          Box {
            size 0.02 0.004 0.02
          }
        ]
      }
      Pose {
        translation -0.31 0.0052 -0.13
        children [
          Box {
            size 0.02 0.004 0.02
          }
        ]
      }
      Pose {
        translation -0.31 0.0052 -0.19
        children [
          Box {
            size 0.02 0.004 0.02
          }
        ]
      }
      Pose {
        translation -0.31 0.0052 -0.25
        children [
          Box {
            size 0.02 0.004 0.02
          }
        ]
      }
      Pose {
        translation -0.31 0.0052 -0.31
        children [
          Box {
            size 0.02 0.004 0.02
          }
        ]
      }
      Pose {
        translation -0.25 0.0052 -0.01
        children [
          Box {
            size 0.02 0.004 0.02
          }
        ]
      }
      Pose {
        translation -0.25 0.0052 -0.07
        children [
          Box {
            size 0.02 0.004 0.02
          }
        ]
      }
      Pose {
        translation -0.25 0.0052 -0.13
        children [
          Box {
            size 0.02 0.004 0.02
          }
        ]
      }
      Pose {
        translation -0.25 0.0052 -0.19
        children [
          Box {
            size 0.02 0.004 0.02
          }
        ]
      }
      Pose {
        translation -0.25 0.0052 -0.25
        children [
          Box {
            size 0.02 0.004 0.02
          }
        ]
      }
      Pose {
        translation -0.25 0.0052 -0.31
        children [
          Box {
            size 0.02 0.004 0.02
          }
        ]
      }
      Pose {
        translation -0.19 0.0052 -0.01
        children [
          Box {
            size 0.02 0.004 0.02
          }
        ]
      }
      Pose {
        translation -0.19 0.0052 -0.07
        children [
          Box {
            size 0.02 0.004 0.02
          }
        ]
      }
      Pose {
        translation -0.19 0.0052 -0.13
        children [
          Box {
            size 0.02 0.004 0.02
          }
        ]
      }
      Pose {
        translation -0.19 0.0052 -0.19
        children [
          Box {
            size 0.02 0.004 0.02
          }
        ]
      }
      Pose {
        translation -0.19 0.0052 -0.25
        children [
          Box {
            size 0.02 0.004 0.02
          }
        ]
      }
      Pose {
        translation -0.19 0.0052 -0.31
        children [
          Box {
            size 0.02 0.004 0.02
          }
        ]
      }
      Pose {
        translation -0.13 0.0052 -0.01
        children [
          Box {
            size 0.02 0.004 0.02
          }
        ]
      }
      Pose {
        translation -0.13 0.0052 -0.07
        children [
          Box {
            size 0.02 0.004 0.02
          }
        ]
      }
      Pose {
        translation -0.13 0.0052 -0.13
        children [
          Box {
            size 0.02 0.004 0.02
          }
        ]
      }
      Pose {
        translation -0.13 0.0052 -0.19
        children [
          Box {
            size 0.02 0.004 0.02
          }
        ]
      }
      Pose {
        translation -0.13 0.0052 -0.25
        children [
          Box {
            size 0.02 0.004 0.02
          }
        ]
      }
      Pose {
        translation -0.13 0.0052 -0.31
        children [
          Box {
            size 0.02 0.004 0.02
          }
        ]
      }
      Pose {
        translation -0.07 0.0052 -0.01
        children [
          Box {
            size 0.02 0.004 0.02
          }
        ]
      }
      Pose {
        translation -0.07 0.0052 -0.07
        children [
          Box {
            size 0.02 0.004 0.02
          }
        ]
      }
      Pose {
        translation -0.07 0.0052 -0.13
        children [
          Box {
            size 0.02 0.004 0.02
          }
        ]
      }
      Pose {
        translation -0.07 0.0052 -0.19
        children [
          Box {
            size 0.02 0.004 0.02
          }
        ]
      }
      Pose {
        translation -0.07 0.0052 -0.25
        children [
          Box {
            size 0.02 0.004 0.02
          }
        ]
      }
      Pose {
        translation -0.07 0.0052 -0.31
        children [
          Box {
            size 0.02 0.004 0.02
          }
        ]
      }
      Pose {
        translation -0.01 0.0052 -0.01
        children [
          Box {
            size 0.02 0.004 0.02
          }
        ]
      }
      Pose {
        translation -0.01 0.0052 -0.07
        children [
          Box {
            size 0.02 0.004 0.02
          }
        ]
      }
      Pose {
        translation -0.01 0.0052 -0.13
        children [
          Box {
            size 0.02 0.004 0.02
          }
        ]
      }
      Pose {
        translation -0.01 0.0052 -0.19
        children [
          Box {
            size 0.02 0.004 0.02
          }
        ]
      }
      Pose {
        translation -0.01 0.0052 -0.25
        children [
          Box {
            size 0.02 0.004 0.02
          }
        ]
      }
      Pose {
        translation -0.01 0.0052 -0.31
        children [
          Box {
            size 0.02 0.004 0.02
          }
        ]
      }
      Pose {
        translation -0.500961 0.0033 -0.17
        rotation 0 0 -1 0
        children [
          Box {
            size 1 0.0034 0.34
          }
        ]
      }
    ]
  }
}
