#VRML_SIM R2025a utf8

EXTERNPROTO "https://raw.githubusercontent.com/cyberbotics/webots/R2025a/projects/objects/backgrounds/protos/TexturedBackground.proto"
EXTERNPROTO "https://raw.githubusercontent.com/cyberbotics/webots/R2025a/projects/objects/backgrounds/protos/TexturedBackgroundLight.proto"
EXTERNPROTO "https://raw.githubusercontent.com/cyberbotics/webots/R2025a/projects/objects/floors/protos/RectangleArena.proto"

WorldInfo {
  contactProperties [
    ContactProperties {
      material1 "rubber"
      material2 "whiteboard"
      coulombFriction [
        0.7
      ]
    }
  ]
}
Viewpoint {
  orientation -0.22621903483761696 0.3997686399970203 0.8882623389247513 1.054045364897764
  position -2.0667200369226086 -2.96126071140145 1.915006017319906
}
TexturedBackground {
}
TexturedBackgroundLight {
}
Viewpoint {
  orientation -0.06916053678155334 0.19066953649016896 0.9792149651668481 1.1849114539041599
  position -0.7826274762082587 -0.6442941205430126 0.3385178633892179
}
TexturedBackground {
}
TexturedBackgroundLight {
  luminosity 0
}
RectangleArena {
  floorSize 3 3
}

DEF WAYPOINT_MARKER Solid {
  translation 0 0 0.002
  children [
    Shape {
      appearance PBRAppearance {
        baseColor 1 0 0    # red
        roughness 1
        metalness 0
      }
      geometry Cylinder {
        radius 0.03
        height 0.002
      }
    }
  ]
  boundingObject NULL
  physics NULL
}

DEF POLULU_ROBOT Robot {
  translation -0.3883956456954819 0.31908081080525047 0.13402602754690568
  rotation -0.003925631041359226 -0.18544216069669694 0.9826473398208878 -3.122877257747942
  children [
    Display {
      width 230
      height 48
    }
    InertialUnit {
      name "imu"
    }
    GPS {
    }
    Shape {
      appearance PBRAppearance {
        roughness 1
        metalness 0
      }
      geometry Mesh {
        url [
          "../Models/bodywithoutcaster.obj"
        ]
      }
      castShadows FALSE
      isPickable FALSE
    }
    BallJoint {
      jointParameters BallJointParameters {
        position -1476.4283418183486
        anchor 0 0.0404 -0.0096
      }
      jointParameters2 JointParameters {
        position 27.0294292437525
        axis 1 0 0
      }
      jointParameters3 JointParameters {
        position -105.98317909389652
        axis 0 1 0
      }
      endPoint Solid {
        translation -0.033044191917233345 0.040784567584316866 0.015783488736276913
        rotation -0.6758547702258138 -0.6679504185036306 0.31154866069979675 2.5655596920780614
        children [
          Shape {
            appearance PBRAppearance {
              roughness 1
              metalness 0
            }
            geometry Mesh {
              url [
                "../Models/caster.obj"
              ]
            }
            castShadows FALSE
            isPickable FALSE
          }
        ]
        name "caster"
        boundingObject Pose {
          translation 0 0.0404 -0.00963
          children [
            Sphere {
              radius 0.00635
              subdivision 3
            }
          ]
        }
        physics Physics {
        }
        linearVelocity -0.02862053810432463 0.06118980088731846 0.021143257506382372
        angularVelocity 13.417977348489757 -16.995544131752467 35.363392576633395
      }
    }
    HingeJoint {
      jointParameters HingeJointParameters {
        position 1941.6457170207536
      }
      device [
        RotationalMotor {
          name "LeftMotor"
          maxVelocity 75.4
        }
      ]
      endPoint Solid {
        translation 0.04149947459869662 -0.0003711236842286068 -1.7606454827978713e-06
        rotation 0.19500420226367673 -0.9604037383276315 -0.19899251369289625 1.6048922085608361
        children [
          DEF wheel Shape {
            appearance PBRAppearance {
              roughness 1
              metalness 0
            }
            geometry Cylinder {
              height 0.0068
              radius 0.016
              subdivision 500
            }
            castShadows FALSE
            isPickable FALSE
          }
        ]
        contactMaterial "rubber"
        boundingObject USE wheel
        physics Physics {
        }
        linearVelocity -0.0008290429626411588 0.07469476094628201 0.025740443553725394
        angularVelocity -4.92626997490046 -0.04780504171716519 -0.02003294018136278
      }
    }
    HingeJoint {
      jointParameters HingeJointParameters {
        position 2555.454253392253
      }
      device [
        DEF RightMotor RotationalMotor {
          name "RightMotor"
          maxVelocity 75.4
        }
      ]
      endPoint Solid {
        translation -0.04149868078943599 0.0003680579194722509 -0.0003726856316420649
        rotation -0.6186883100557193 0.4872094568558391 -0.616321117722439 2.2294888045135455
        children [
          USE wheel
        ]
        contactMaterial "rubber"
        boundingObject USE wheel
        physics Physics {
        }
        linearVelocity -0.0008271210811611586 0.07440897299933716 0.025676830216794837
        angularVelocity -4.926269963873789 -0.04780527913746469 -0.020033192830910963
      }
    }
  ]
  boundingObject Pose {
    translation 0 0 0.0025
    children [
      Cylinder {
        height 0.0266
        radius 0.0484
        subdivision 50
      }
    ]
  }
  physics Physics {
    mass 0.158
    centerOfMass [
      0 0 0
    ]
  }
  supervisor TRUE
  controller "autonomous_navigation"
  linearVelocity -0.0008381259721683106 0.07539901972560471 0.02615773417009996
  angularVelocity 0.0727199594797906 0.03396303943331407 0.038531121912268984
}
Solid {
  translation -0.34 0.82 4.02622e-06
  rotation 0.5773509358554485 0.5773489358556708 0.5773509358554485 2.0944
  children [
    DEF obstacle Shape {
      appearance PBRAppearance {
        baseColor 0 0 0
        roughness 1
        metalness 0
      }
      geometry Mesh {
        url [
          "../Models/ramp.obj"
        ]
      }
    }
  ]
  contactMaterial "whiteboard"
  boundingObject Group {
    children [
      Pose {
        translation -0.590961 0.033 0
        rotation 0 0 1 0.3321694619948667
        children [
          Box {
            size 0.76 0.1 0.28
          }
        ]
      }
      Pose {
        translation -0.01 0.1024 0
        children [
          Box {
            size 0.25 0.25 0.31
          }
        ]
      }
      Pose {
        translation -0.108 -0.2061 0
        children [
          Capsule {
            height 0.4
            radius 0.434
            subdivision 500
          }
        ]
      }
    ]
  }
}
