#VRML_SIM R2025a utf8

EXTERNPROTO "https://raw.githubusercontent.com/cyberbotics/webots/R2025a/projects/objects/backgrounds/protos/TexturedBackground.proto"
EXTERNPROTO "https://raw.githubusercontent.com/cyberbotics/webots/R2025a/projects/objects/backgrounds/protos/TexturedBackgroundLight.proto"
EXTERNPROTO "https://raw.githubusercontent.com/cyberbotics/webots/R2025a/projects/objects/floors/protos/RectangleArena.proto"

WorldInfo {
  contactProperties [
    ContactProperties {
      material1 "rubber"
      material2 "whiteboard"
      coulombFriction [
        0.7
      ]
    }
  ]
}
Viewpoint {
  orientation -0.22621903483761696 0.3997686399970203 0.8882623389247513 1.054045364897764
  position -2.0667200369226086 -2.96126071140145 1.915006017319906
}
TexturedBackground {
}
TexturedBackgroundLight {
}
Viewpoint {
  orientation -0.2607751354996161 0.21295658304832096 0.9416187245597554 1.9303222977511383
  position 0.04679775880281367 -0.40514321266925507 0.6151803099350407
}
TexturedBackground {
}
TexturedBackgroundLight {
  luminosity 0
}
RectangleArena {
  floorSize 3 3
}
Robot {
  translation -0.3875756486717132 0.24695899867133392 0.10891804869250928
  rotation 0.003208374571936722 -0.1766312421146376 0.9842718682567568 -3.1246035205407403
  children [
    Shape {
      appearance PBRAppearance {
        roughness 1
        metalness 0
      }
      geometry Mesh {
        url [
          "../../../Downloads/bodywithoutball1.obj"
        ]
      }
      castShadows FALSE
      isPickable FALSE
    }
    BallJoint {
      jointParameters BallJointParameters {
        position -1458.9467289025101
        anchor 0 0.0404 -0.0096
      }
      jointParameters2 JointParameters {
        position 26.42817227555493
        axis 1 0 0
      }
      jointParameters3 JointParameters {
        position -111.31323029217353
        axis 0 1 0
      }
      endPoint Solid {
        translation -0.02057015397755224 0.008980362616282433 -0.02710106093946367
        rotation -0.21559670705072154 -0.962755708789262 -0.16315485007369915 2.823040010006451
        children [
          Shape {
            appearance PBRAppearance {
              roughness 1
              metalness 0
            }
            geometry Mesh {
              url [
                "../../../Downloads/ballonly.obj"
              ]
            }
            castShadows FALSE
            isPickable FALSE
          }
        ]
        name "caster"
        boundingObject Pose {
          translation 0 0.0404 -0.00963
          children [
            Sphere {
              radius 0.00635
              subdivision 3
            }
          ]
        }
        physics Physics {
        }
        linearVelocity -0.006212531199839701 0.08511075044429353 0.030276715872854878
        angularVelocity -14.647558468081952 -8.763500348381449 22.315448739290602
      }
    }
    HingeJoint {
      jointParameters HingeJointParameters {
        position 1936.8559318140105
      }
      device [
        RotationalMotor {
          name "LeftMotor"
        }
      ]
      endPoint Solid {
        translation 0.04149947459869663 -2.6939529890690863e-05 -0.0003701488222285724
        rotation -0.6318609331931567 0.4502175712489334 0.6309167137134541 3.997055489066442
        children [
          DEF wheel Shape {
            appearance PBRAppearance {
              roughness 1
              metalness 0
            }
            geometry Cylinder {
              height 0.0068
              radius 0.016
              subdivision 500
            }
            castShadows FALSE
            isPickable FALSE
          }
        ]
        contactMaterial "rubber"
        boundingObject USE wheel
        physics Physics {
        }
        linearVelocity -0.0008658294374513257 0.07841501289495954 0.02744565061988205
        angularVelocity -5.189767731025456 -0.05177787308371182 -0.015832787339386274
      }
    }
    HingeJoint {
      jointParameters HingeJointParameters {
        position 2550.6644681864477
      }
      device [
        DEF RightMotor RotationalMotor {
          name "RightMotor"
        }
      ]
      endPoint Solid {
        translation -0.04149868078943599 0.00040002782509042985 0.0003381404312886988
        rotation 0.15208640817514935 -0.976492647682994 0.1527476136292729 4.69381011527047
        children [
          USE wheel
        ]
        contactMaterial "rubber"
        boundingObject USE wheel
        physics Physics {
        }
        linearVelocity -0.0008677736191881509 0.07852271329377003 0.027634827218354724
        angularVelocity -5.189767742624676 -0.05177807274922185 -0.01583303625318806
      }
    }
  ]
  boundingObject Pose {
    translation 0 0 0.0025
    children [
      Cylinder {
        height 0.0266
        radius 0.0484
        subdivision 50
      }
    ]
  }
  physics Physics {
    mass 0.158
    centerOfMass [
      0 0 0
    ]
  }
  controller "my_controller"
  linearVelocity -0.0008695677190362949 0.07900343070775613 0.02668285986233819
  angularVelocity -0.1906283988434661 0.04015598597810488 -0.028849432741419698
}
Solid {
  translation -0.34 0.82 4.02622e-06
  rotation 0.5773509358554485 0.5773489358556708 0.5773509358554485 2.0944
  children [
    DEF obstacle Shape {
      appearance PBRAppearance {
        baseColor 0 0 0
        roughness 1
        metalness 0
      }
      geometry Mesh {
        url [
          "../../../Downloads/ramp.obj"
        ]
      }
    }
  ]
  contactMaterial "whiteboard"
  boundingObject Group {
    children [
      Pose {
        translation -0.590961 0.033 0
        rotation 0 0 1 0.3321694619948667
        children [
          Box {
            size 0.76 0.1 0.28
          }
        ]
      }
      Pose {
        translation -0.01 0.1024 0
        children [
          Box {
            size 0.25 0.25 0.31
          }
        ]
      }
      Pose {
        translation -0.108 -0.2061 0
        children [
          Capsule {
            height 0.4
            radius 0.434
            subdivision 500
          }
        ]
      }
    ]
  }
}
