#VRML_SIM R2025a utf8

EXTERNPROTO "https://raw.githubusercontent.com/cyberbotics/webots/R2025a/projects/objects/backgrounds/protos/TexturedBackground.proto"
EXTERNPROTO "https://raw.githubusercontent.com/cyberbotics/webots/R2025a/projects/objects/backgrounds/protos/TexturedBackgroundLight.proto"
EXTERNPROTO "https://raw.githubusercontent.com/cyberbotics/webots/R2025a/projects/objects/floors/protos/RectangleArena.proto"

WorldInfo {
  contactProperties [
    ContactProperties {
      material1 "rubber"
      material2 "parchment_paper"
      coulombFriction [
        0.4
      ]
    }
    ContactProperties {
      material1 "rubber"
      material2 "ground"
      coulombFriction [
        0.8
      ]
    }
    ContactProperties {
      material1 "rubber"
      material2 "whiteboard"
      coulombFriction [
        0.7
      ]
    }
    ContactProperties {
      material1 "rubber"
      material2 "bumpGround"
      coulombFriction [
        0.85
      ]
    }
  ]
}
Viewpoint {
  orientation -0.22621903483761696 0.3997686399970203 0.8882623389247513 1.054045364897764
  position -2.0667200369226086 -2.96126071140145 1.915006017319906
}
TexturedBackground {
}
TexturedBackgroundLight {
}
Viewpoint {
  orientation -0.35321206818038 -0.593210582705938 0.7234241076003896 5.146478950188634
  position -0.527276593292172 0.8469910743567715 1.1906350914247112
}
TexturedBackground {
}
TexturedBackgroundLight {
  luminosity 0
}
RectangleArena {
  contactMaterial "parchment_paper"
  floorSize 3 3
}
DEF WAYPOINT_MARKER Solid {
  translation -0.0716 -0.0852 0.002
  children [
    Shape {
      appearance PBRAppearance {
        baseColor 1 0 0
        transparency 0.8
        roughness 1
        metalness 0
        emissiveColor 1 0 0
      }
      geometry Cylinder {
        height 1
        radius 0.03
      }
    }
  ]
}
DEF POLULU_ROBOT Robot {
  translation -0.2893714185248192 -0.06534531160069765 0.12671205341938518
  rotation -0.17542133289787284 -0.16654366377423366 0.9703043666917041 1.5973878986065795
  children [
    Display {
      width 230
    }
    InertialUnit {
      name "imu"
    }
    GPS {
    }
    Shape {
      appearance PBRAppearance {
        roughness 1
        metalness 0
      }
      geometry Mesh {
        url [
          "../../../Downloads/bodywithoutcaster.obj"
        ]
      }
      castShadows FALSE
      isPickable FALSE
    }
    BallJoint {
      jointParameters BallJointParameters {
        position -1434.3532610570921
        anchor 0 0.0404 -0.0096
      }
      jointParameters2 JointParameters {
        position 31.973812266498932
        axis 1 0 0
      }
      jointParameters3 JointParameters {
        position -14.868984808942395
        axis 0 1 0
      }
      endPoint Solid {
        translation 0.039254687481421933 0.052930282866282846 -0.0030583638004607894
        rotation 0.7875330291320335 -0.6120782393738112 0.07177713362331493 -2.8951346940964298
        children [
          Shape {
            appearance PBRAppearance {
              roughness 1
              metalness 0
            }
            geometry Mesh {
              url [
                "../Models/caster.obj"
              ]
            }
            castShadows FALSE
            isPickable FALSE
          }
        ]
        name "caster"
        boundingObject Pose {
          translation 0 0.0404 -0.00963
          children [
            Sphere {
              radius 0.00635
              subdivision 3
            }
          ]
        }
        physics Physics {
        }
        linearVelocity 0.000879348635505893 -0.03387030904370908 0.00031419698219597525
        angularVelocity 3.8961968092785213 0.17139762996837837 6.577759334858344
      }
    }
    HingeJoint {
      jointParameters HingeJointParameters {
        position 2329.7731701739654
      }
      device [
        RotationalMotor {
          name "LeftMotor"
          maxVelocity 75.4
        }
      ]
      endPoint Solid {
        translation 0.04149947459869657 -5.381042599859599e-05 0.00036720610959212045
        rotation -0.4442911984920047 -0.7815648246882418 0.4379061038083112 1.8125663474095925
        children [
          DEF wheel Shape {
            appearance PBRAppearance {
              roughness 1
              metalness 0
            }
            geometry Cylinder {
              height 0.0068
              radius 0.016
              subdivision 500
            }
            castShadows FALSE
            isPickable FALSE
          }
        ]
        contactMaterial "rubber"
        boundingObject USE wheel
        physics Physics {
        }
        linearVelocity -4.788052413106443e-06 4.841790672500488e-06 3.6874894801428875e-05
        angularVelocity -0.00027736494962735407 0.0003165195951017638 -6.237433370668343e-05
      }
    }
    HingeJoint {
      jointParameters HingeJointParameters {
        position 3207.544228758969
      }
      device [
        DEF RightMotor RotationalMotor {
          name "RightMotor"
          maxVelocity 75.4
        }
      ]
      endPoint Solid {
        translation -0.04149868078943601 -0.0002879916579893241 -0.0004375180191114961
        rotation -0.7088474694291339 -0.008266179798185771 -0.7053133596887677 3.1561502712997225
        children [
          USE wheel
        ]
        contactMaterial "rubber"
        boundingObject USE wheel
        physics Physics {
        }
        linearVelocity -1.058050896498588e-05 4.273000737316048e-06 5.9690097034226824e-05
        angularVelocity -0.00027737616291905896 0.00031651478302476764 -6.237926736672726e-05
      }
    }
  ]
  boundingObject Pose {
    translation 0 0 0.0025
    children [
      Cylinder {
        height 0.0266
        radius 0.0484
        subdivision 50
      }
    ]
  }
  physics Physics {
    mass 0.158
    centerOfMass [
      0 0 0
    ]
  }
  controller "autonomous_navigation"
  supervisor TRUE
  linearVelocity -7.523098867788575e-06 4.578249102650316e-06 4.831935621853354e-05
  angularVelocity -0.0002773715858434229 0.000316548994139862 -6.237805637064922e-05
}
Solid {
  translation 0.43 -0.0699928 -3.69718e-06
  rotation 0.999999999986531 5.189879999930098e-06 5.50078999992591e-08 1.5708
  children [
    DEF obstacle Shape {
      appearance PBRAppearance {
        baseColor 0 0 0
        roughness 1
        metalness 0
      }
      geometry Mesh {
        url [
          "../../../Downloads/ramp1.obj"
        ]
      }
    }
  ]
  name "ramp"
  contactMaterial "whiteboard"
  boundingObject Group {
    children [
      Pose {
        translation -0.564 0.092 0
        rotation 0 0 1 0.24043831505672397
        children [
          Box {
            size 0.76 0.1 0.28
          }
        ]
      }
      Pose {
        translation -0.0024 0.104 0
        rotation 0 0 1 -0.085
        children [
          Box {
            size 0.25 0.25 0.31
          }
        ]
        rotationStep 0.343
      }
      Pose {
        translation -0.123 -0.1951 0
        children [
          Capsule {
            height 0.4
            radius 0.434
            subdivision 500
          }
        ]
      }
    ]
  }
}
Solid {
  translation 0.58 1.44 5.67207e-06
  rotation 0.5773509358554485 0.5773489358556708 0.5773509358554485 2.0944
  children [
    DEF bump Shape {
      appearance PBRAppearance {
        baseColor 0 0 0
        roughness 1
        metalness 0
      }
      geometry Mesh {
        url [
          "../../../Downloads/bump.obj"
        ]
      }
    }
  ]
  name "bump"
  contactMaterial "bumpGround"
  boundingObject Group {
    children [
      Pose {
        translation -0.97 0.0052 -0.01
        children [
          Box {
            size 0.02 0.004 0.02
          }
        ]
      }
      Pose {
        translation -0.97 0.0052 -0.07
        children [
          Box {
            size 0.02 0.004 0.02
          }
        ]
      }
      Pose {
        translation -0.97 0.0052 -0.13
        children [
          Box {
            size 0.02 0.004 0.02
          }
        ]
      }
      Pose {
        translation -0.97 0.0052 -0.19
        children [
          Box {
            size 0.02 0.004 0.02
          }
        ]
      }
      Pose {
        translation -0.97 0.0052 -0.25
        children [
          Box {
            size 0.02 0.004 0.02
          }
        ]
      }
      Pose {
        translation -0.97 0.0052 -0.31
        children [
          Box {
            size 0.02 0.004 0.02
          }
        ]
      }
      Pose {
        translation -0.91 0.0052 -0.01
        children [
          Box {
            size 0.02 0.004 0.02
          }
        ]
      }
      Pose {
        translation -0.91 0.0052 -0.07
        children [
          Box {
            size 0.02 0.004 0.02
          }
        ]
      }
      Pose {
        translation -0.91 0.0052 -0.13
        children [
          Box {
            size 0.02 0.004 0.02
          }
        ]
      }
      Pose {
        translation -0.91 0.0052 -0.19
        children [
          Box {
            size 0.02 0.004 0.02
          }
        ]
      }
      Pose {
        translation -0.91 0.0052 -0.25
        children [
          Box {
            size 0.02 0.004 0.02
          }
        ]
      }
      Pose {
        translation -0.91 0.0052 -0.31
        children [
          Box {
            size 0.02 0.004 0.02
          }
        ]
      }
      Pose {
        translation -0.85 0.0052 -0.01
        children [
          Box {
            size 0.02 0.004 0.02
          }
        ]
      }
      Pose {
        translation -0.85 0.0052 -0.07
        children [
          Box {
            size 0.02 0.004 0.02
          }
        ]
      }
      Pose {
        translation -0.85 0.0052 -0.13
        children [
          Box {
            size 0.02 0.004 0.02
          }
        ]
      }
      Pose {
        translation -0.85 0.0052 -0.19
        children [
          Box {
            size 0.02 0.004 0.02
          }
        ]
      }
      Pose {
        translation -0.85 0.0052 -0.25
        children [
          Box {
            size 0.02 0.004 0.02
          }
        ]
      }
      Pose {
        translation -0.85 0.0052 -0.31
        children [
          Box {
            size 0.02 0.004 0.02
          }
        ]
      }
      Pose {
        translation -0.79 0.0052 -0.01
        children [
          Box {
            size 0.02 0.004 0.02
          }
        ]
      }
      Pose {
        translation -0.79 0.0052 -0.07
        children [
          Box {
            size 0.02 0.004 0.02
          }
        ]
      }
      Pose {
        translation -0.79 0.0052 -0.13
        children [
          Box {
            size 0.02 0.004 0.02
          }
        ]
      }
      Pose {
        translation -0.79 0.0052 -0.19
        children [
          Box {
            size 0.02 0.004 0.02
          }
        ]
      }
      Pose {
        translation -0.79 0.0052 -0.25
        children [
          Box {
            size 0.02 0.004 0.02
          }
        ]
      }
      Pose {
        translation -0.79 0.0052 -0.31
        children [
          Box {
            size 0.02 0.004 0.02
          }
        ]
      }
      Pose {
        translation -0.73 0.0052 -0.01
        children [
          Box {
            size 0.02 0.004 0.02
          }
        ]
      }
      Pose {
        translation -0.73 0.0052 -0.07
        children [
          Box {
            size 0.02 0.004 0.02
          }
        ]
      }
      Pose {
        translation -0.73 0.0052 -0.13
        children [
          Box {
            size 0.02 0.004 0.02
          }
        ]
      }
      Pose {
        translation -0.73 0.0052 -0.19
        children [
          Box {
            size 0.02 0.004 0.02
          }
        ]
      }
      Pose {
        translation -0.73 0.0052 -0.25
        children [
          Box {
            size 0.02 0.004 0.02
          }
        ]
      }
      Pose {
        translation -0.73 0.0052 -0.31
        children [
          Box {
            size 0.02 0.004 0.02
          }
        ]
      }
      Pose {
        translation -0.67 0.0052 -0.01
        children [
          Box {
            size 0.02 0.004 0.02
          }
        ]
      }
      Pose {
        translation -0.67 0.0052 -0.07
        children [
          Box {
            size 0.02 0.004 0.02
          }
        ]
      }
      Pose {
        translation -0.67 0.0052 -0.13
        children [
          Box {
            size 0.02 0.004 0.02
          }
        ]
      }
      Pose {
        translation -0.67 0.0052 -0.19
        children [
          Box {
            size 0.02 0.004 0.02
          }
        ]
      }
      Pose {
        translation -0.67 0.0052 -0.25
        children [
          Box {
            size 0.02 0.004 0.02
          }
        ]
      }
      Pose {
        translation -0.67 0.0052 -0.31
        children [
          Box {
            size 0.02 0.004 0.02
          }
        ]
      }
      Pose {
        translation -0.61 0.0052 -0.01
        children [
          Box {
            size 0.02 0.004 0.02
          }
        ]
      }
      Pose {
        translation -0.61 0.0052 -0.07
        children [
          Box {
            size 0.02 0.004 0.02
          }
        ]
      }
      Pose {
        translation -0.61 0.0052 -0.13
        children [
          Box {
            size 0.02 0.004 0.02
          }
        ]
      }
      Pose {
        translation -0.61 0.0052 -0.19
        children [
          Box {
            size 0.02 0.004 0.02
          }
        ]
      }
      Pose {
        translation -0.61 0.0052 -0.25
        children [
          Box {
            size 0.02 0.004 0.02
          }
        ]
      }
      Pose {
        translation -0.61 0.0052 -0.31
        children [
          Box {
            size 0.02 0.004 0.02
          }
        ]
      }
      Pose {
        translation -0.55 0.0052 -0.01
        children [
          Box {
            size 0.02 0.004 0.02
          }
        ]
      }
      Pose {
        translation -0.55 0.0052 -0.07
        children [
          Box {
            size 0.02 0.004 0.02
          }
        ]
      }
      Pose {
        translation -0.55 0.0052 -0.13
        children [
          Box {
            size 0.02 0.004 0.02
          }
        ]
      }
      Pose {
        translation -0.55 0.0052 -0.19
        children [
          Box {
            size 0.02 0.004 0.02
          }
        ]
      }
      Pose {
        translation -0.55 0.0052 -0.25
        children [
          Box {
            size 0.02 0.004 0.02
          }
        ]
      }
      Pose {
        translation -0.55 0.0052 -0.31
        children [
          Box {
            size 0.02 0.004 0.02
          }
        ]
      }
      Pose {
        translation -0.49 0.0052 -0.01
        children [
          Box {
            size 0.02 0.004 0.02
          }
        ]
      }
      Pose {
        translation -0.49 0.0052 -0.07
        children [
          Box {
            size 0.02 0.004 0.02
          }
        ]
      }
      Pose {
        translation -0.49 0.0052 -0.13
        children [
          Box {
            size 0.02 0.004 0.02
          }
        ]
      }
      Pose {
        translation -0.49 0.0052 -0.19
        children [
          Box {
            size 0.02 0.004 0.02
          }
        ]
      }
      Pose {
        translation -0.49 0.0052 -0.25
        children [
          Box {
            size 0.02 0.004 0.02
          }
        ]
      }
      Pose {
        translation -0.49 0.0052 -0.31
        children [
          Box {
            size 0.02 0.004 0.02
          }
        ]
      }
      Pose {
        translation -0.43 0.0052 -0.01
        children [
          Box {
            size 0.02 0.004 0.02
          }
        ]
      }
      Pose {
        translation -0.43 0.0052 -0.07
        children [
          Box {
            size 0.02 0.004 0.02
          }
        ]
      }
      Pose {
        translation -0.43 0.0052 -0.13
        children [
          Box {
            size 0.02 0.004 0.02
          }
        ]
      }
      Pose {
        translation -0.43 0.0052 -0.19
        children [
          Box {
            size 0.02 0.004 0.02
          }
        ]
      }
      Pose {
        translation -0.43 0.0052 -0.25
        children [
          Box {
            size 0.02 0.004 0.02
          }
        ]
      }
      Pose {
        translation -0.43 0.0052 -0.31
        children [
          Box {
            size 0.02 0.004 0.02
          }
        ]
      }
      Pose {
        translation -0.37 0.0052 -0.01
        children [
          Box {
            size 0.02 0.004 0.02
          }
        ]
      }
      Pose {
        translation -0.37 0.0052 -0.07
        children [
          Box {
            size 0.02 0.004 0.02
          }
        ]
      }
      Pose {
        translation -0.37 0.0052 -0.13
        children [
          Box {
            size 0.02 0.004 0.02
          }
        ]
      }
      Pose {
        translation -0.37 0.0052 -0.19
        children [
          Box {
            size 0.02 0.004 0.02
          }
        ]
      }
      Pose {
        translation -0.37 0.0052 -0.25
        children [
          Box {
            size 0.02 0.004 0.02
          }
        ]
      }
      Pose {
        translation -0.37 0.0052 -0.31
        children [
          Box {
            size 0.02 0.004 0.02
          }
        ]
      }
      Pose {
        translation -0.31 0.0052 -0.01
        children [
          Box {
            size 0.02 0.004 0.02
          }
        ]
      }
      Pose {
        translation -0.31 0.0052 -0.07
        children [
          Box {
            size 0.02 0.004 0.02
          }
        ]
      }
      Pose {
        translation -0.31 0.0052 -0.13
        children [
          Box {
            size 0.02 0.004 0.02
          }
        ]
      }
      Pose {
        translation -0.31 0.0052 -0.19
        children [
          Box {
            size 0.02 0.004 0.02
          }
        ]
      }
      Pose {
        translation -0.31 0.0052 -0.25
        children [
          Box {
            size 0.02 0.004 0.02
          }
        ]
      }
      Pose {
        translation -0.31 0.0052 -0.31
        children [
          Box {
            size 0.02 0.004 0.02
          }
        ]
      }
      Pose {
        translation -0.25 0.0052 -0.01
        children [
          Box {
            size 0.02 0.004 0.02
          }
        ]
      }
      Pose {
        translation -0.25 0.0052 -0.07
        children [
          Box {
            size 0.02 0.004 0.02
          }
        ]
      }
      Pose {
        translation -0.25 0.0052 -0.13
        children [
          Box {
            size 0.02 0.004 0.02
          }
        ]
      }
      Pose {
        translation -0.25 0.0052 -0.19
        children [
          Box {
            size 0.02 0.004 0.02
          }
        ]
      }
      Pose {
        translation -0.25 0.0052 -0.25
        children [
          Box {
            size 0.02 0.004 0.02
          }
        ]
      }
      Pose {
        translation -0.25 0.0052 -0.31
        children [
          Box {
            size 0.02 0.004 0.02
          }
        ]
      }
      Pose {
        translation -0.19 0.0052 -0.01
        children [
          Box {
            size 0.02 0.004 0.02
          }
        ]
      }
      Pose {
        translation -0.19 0.0052 -0.07
        children [
          Box {
            size 0.02 0.004 0.02
          }
        ]
      }
      Pose {
        translation -0.19 0.0052 -0.13
        children [
          Box {
            size 0.02 0.004 0.02
          }
        ]
      }
      Pose {
        translation -0.19 0.0052 -0.19
        children [
          Box {
            size 0.02 0.004 0.02
          }
        ]
      }
      Pose {
        translation -0.19 0.0052 -0.25
        children [
          Box {
            size 0.02 0.004 0.02
          }
        ]
      }
      Pose {
        translation -0.19 0.0052 -0.31
        children [
          Box {
            size 0.02 0.004 0.02
          }
        ]
      }
      Pose {
        translation -0.13 0.0052 -0.01
        children [
          Box {
            size 0.02 0.004 0.02
          }
        ]
      }
      Pose {
        translation -0.13 0.0052 -0.07
        children [
          Box {
            size 0.02 0.004 0.02
          }
        ]
      }
      Pose {
        translation -0.13 0.0052 -0.13
        children [
          Box {
            size 0.02 0.004 0.02
          }
        ]
      }
      Pose {
        translation -0.13 0.0052 -0.19
        children [
          Box {
            size 0.02 0.004 0.02
          }
        ]
      }
      Pose {
        translation -0.13 0.0052 -0.25
        children [
          Box {
            size 0.02 0.004 0.02
          }
        ]
      }
      Pose {
        translation -0.13 0.0052 -0.31
        children [
          Box {
            size 0.02 0.004 0.02
          }
        ]
      }
      Pose {
        translation -0.07 0.0052 -0.01
        children [
          Box {
            size 0.02 0.004 0.02
          }
        ]
      }
      Pose {
        translation -0.07 0.0052 -0.07
        children [
          Box {
            size 0.02 0.004 0.02
          }
        ]
      }
      Pose {
        translation -0.07 0.0052 -0.13
        children [
          Box {
            size 0.02 0.004 0.02
          }
        ]
      }
      Pose {
        translation -0.07 0.0052 -0.19
        children [
          Box {
            size 0.02 0.004 0.02
          }
        ]
      }
      Pose {
        translation -0.07 0.0052 -0.25
        children [
          Box {
            size 0.02 0.004 0.02
          }
        ]
      }
      Pose {
        translation -0.07 0.0052 -0.31
        children [
          Box {
            size 0.02 0.004 0.02
          }
        ]
      }
      Pose {
        translation -0.01 0.0052 -0.01
        children [
          Box {
            size 0.02 0.004 0.02
          }
        ]
      }
      Pose {
        translation -0.01 0.0052 -0.07
        children [
          Box {
            size 0.02 0.004 0.02
          }
        ]
      }
      Pose {
        translation -0.01 0.0052 -0.13
        children [
          Box {
            size 0.02 0.004 0.02
          }
        ]
      }
      Pose {
        translation -0.01 0.0052 -0.19
        children [
          Box {
            size 0.02 0.004 0.02
          }
        ]
      }
      Pose {
        translation -0.01 0.0052 -0.25
        children [
          Box {
            size 0.02 0.004 0.02
          }
        ]
      }
      Pose {
        translation -0.01 0.0052 -0.31
        children [
          Box {
            size 0.02 0.004 0.02
          }
        ]
      }
      Pose {
        translation -0.500961 0.0033 -0.17
        rotation 0 0 -1 0
        children [
          Box {
            size 1 0.0034 0.34
          }
        ]
      }
    ]
  }
}
